Workbook

Sheet My Debts
A1: Debt Consolidation Calculator & Snowball Method
A2: Fill in the cream-colored cells. White cells contain formulas: don't edit them. Enter the rate as a percentage (e.g. 24.99%).
A4: SUMMARY
A5: Total debt | B5: =SUM(D16:D25)
A6: Total minimum payment / month | B6: =SUM(F16:F25)
A7: Extra monthly payment | B7: 150
A8: Total monthly payment | B8: =B6+B7
A9: Weighted average rate | B9: =IFERROR(SUMPRODUCT(D16:D25,E16:E25)/B5,0)
A10: Estimated months | B10: =IF(COUNTIF(H16:H25,"60+")>0,"60+",MAX(H16:H25))
A11: Estimated total interest | B11: =SUM('Payment Schedule'!W6:W65)
A12: Debt-free (estimated) | B12: =IF(B10=0,"—",IF(B10="60+","More than 5 years",TEXT(DATE(YEAR(TODAY()),MONTH(TODAY())+B10,1),"mmmm yyyy")))
A13: Number of debts | B13: =COUNTIF(D16:D25,">0")
A14: MY DEBTS
A15: # | B15: Debt name | C15: Type | D15: Total balance ($) | E15: Annual interest rate % | F15: Monthly minimum payment ($) | G15: Snowball order | H15: Paid off (month)
A16: 1 | B16: Credit card (example) | C16: Credit card | D16: 2500 | E16: 0.2499 | F16: 75 | G16: =IF(D16="","",RANK(D16,$D$16:$D$25,1)+COUNTIF($D$16:D16,D16)-1) | H16: {=IF(G16="","",IFERROR(MATCH(0,INDEX('Payment Schedule'!$C$6:$L$65,0,G16),0),"60+"))}
A17: 2 | B17: Personal loan (example) | C17: Personal loan | D17: 5200 | E17: 0.1299 | F17: 155 | G17: =IF(D17="","",RANK(D17,$D$16:$D$25,1)+COUNTIF($D$16:D17,D17)-1) | H17: {=IF(G17="","",IFERROR(MATCH(0,INDEX('Payment Schedule'!$C$6:$L$65,0,G17),0),"60+"))}
A18: 3 | B18: Auto loan (example) | C18: Auto loan | D18: 8300 | E18: 0.0849 | F18: 225 | G18: =IF(D18="","",RANK(D18,$D$16:$D$25,1)+COUNTIF($D$16:D18,D18)-1) | H18: {=IF(G18="","",IFERROR(MATCH(0,INDEX('Payment Schedule'!$C$6:$L$65,0,G18),0),"60+"))}
A19: 4 | G19: =IF(D19="","",RANK(D19,$D$16:$D$25,1)+COUNTIF($D$16:D19,D19)-1) | H19: {=IF(G19="","",IFERROR(MATCH(0,INDEX('Payment Schedule'!$C$6:$L$65,0,G19),0),"60+"))}
A20: 5 | G20: =IF(D20="","",RANK(D20,$D$16:$D$25,1)+COUNTIF($D$16:D20,D20)-1) | H20: {=IF(G20="","",IFERROR(MATCH(0,INDEX('Payment Schedule'!$C$6:$L$65,0,G20),0),"60+"))}
A21: 6 | G21: =IF(D21="","",RANK(D21,$D$16:$D$25,1)+COUNTIF($D$16:D21,D21)-1) | H21: {=IF(G21="","",IFERROR(MATCH(0,INDEX('Payment Schedule'!$C$6:$L$65,0,G21),0),"60+"))}
A22: 7 | G22: =IF(D22="","",RANK(D22,$D$16:$D$25,1)+COUNTIF($D$16:D22,D22)-1) | H22: {=IF(G22="","",IFERROR(MATCH(0,INDEX('Payment Schedule'!$C$6:$L$65,0,G22),0),"60+"))}
A23: 8 | G23: =IF(D23="","",RANK(D23,$D$16:$D$25,1)+COUNTIF($D$16:D23,D23)-1) | H23: {=IF(G23="","",IFERROR(MATCH(0,INDEX('Payment Schedule'!$C$6:$L$65,0,G23),0),"60+"))}
A24: 9 | G24: =IF(D24="","",RANK(D24,$D$16:$D$25,1)+COUNTIF($D$16:D24,D24)-1) | H24: {=IF(G24="","",IFERROR(MATCH(0,INDEX('Payment Schedule'!$C$6:$L$65,0,G24),0),"60+"))}
A25: 10 | G25: =IF(D25="","",RANK(D25,$D$16:$D$25,1)+COUNTIF($D$16:D25,D25)-1) | H25: {=IF(G25="","",IFERROR(MATCH(0,INDEX('Payment Schedule'!$C$6:$L$65,0,G25),0),"60+"))}
A27: CONSOLIDATION (optional)
A28: Consolidation loan annual rate | B28: 0.12
A29: Term (months) | B29: 36
A30: Consolidated monthly payment | B30: =IFERROR(PMT(B28/12,B29,-B5),0)
A31: Total interest with consolidation | B31: =IFERROR(B30*B29-B5,0)
A32: Savings vs. snowball | B32: =B11-B31
A33: =IF(B5=0,"",IF(B32>0,"✅ Consolidation would save you "&TEXT(B32,"$#,##0.00"),IF(B32<0,"⚠️ The snowball works out better for you by "&TEXT(ABS(B32),"$#,##0.00"),"◦ No meaningful difference")))

Sheet Snowball Plan
A1: Snowball Plan — your attack order
A2: The snowball method orders your debts from smallest to largest balance. You pay the minimum on all of them and throw your entire extra payment at the smallest one. When it's paid off, that payment rolls into attacking the next one. Quick wins that keep you motivated.
A3: Your extra monthly payment: | B3: ='My Debts'!B7 | C3: (change it on the My Debts tab)
A5: Order | B5: Debt | C5: Starting balance | D5: Rate | E5: Minimum payment | F5: Paid off (month) | G5: Strategy
A6: 1 | B6: {=IFERROR(INDEX('My Debts'!$B$16:$B$25,MATCH($A6,'My Debts'!$G$16:$G$25,0)),"")} | C6: {=IFERROR(INDEX('My Debts'!$D$16:$D$25,MATCH($A6,'My Debts'!$G$16:$G$25,0)),"")} | D6: {=IFERROR(INDEX('My Debts'!$E$16:$E$25,MATCH($A6,'My Debts'!$G$16:$G$25,0)),"")} | E6: {=IFERROR(INDEX('My Debts'!$F$16:$F$25,MATCH($A6,'My Debts'!$G$16:$G$25,0)),"")} | F6: {=IFERROR(INDEX('My Debts'!$H$16:$H$25,MATCH($A6,'My Debts'!$G$16:$G$25,0)),"")} | G6: =IF($B6="","",IF($A6=1,"🎯 ATTACK THIS FIRST: pay the minimum + all your extra payment here.","Pay only the minimum until it's your turn."))
A7: 2 | B7: {=IFERROR(INDEX('My Debts'!$B$16:$B$25,MATCH($A7,'My Debts'!$G$16:$G$25,0)),"")} | C7: {=IFERROR(INDEX('My Debts'!$D$16:$D$25,MATCH($A7,'My Debts'!$G$16:$G$25,0)),"")} | D7: {=IFERROR(INDEX('My Debts'!$E$16:$E$25,MATCH($A7,'My Debts'!$G$16:$G$25,0)),"")} | E7: {=IFERROR(INDEX('My Debts'!$F$16:$F$25,MATCH($A7,'My Debts'!$G$16:$G$25,0)),"")} | F7: {=IFERROR(INDEX('My Debts'!$H$16:$H$25,MATCH($A7,'My Debts'!$G$16:$G$25,0)),"")} | G7: =IF($B7="","",IF($A7=1,"🎯 ATTACK THIS FIRST: pay the minimum + all your extra payment here.","Pay only the minimum until it's your turn."))
A8: 3 | B8: {=IFERROR(INDEX('My Debts'!$B$16:$B$25,MATCH($A8,'My Debts'!$G$16:$G$25,0)),"")} | C8: {=IFERROR(INDEX('My Debts'!$D$16:$D$25,MATCH($A8,'My Debts'!$G$16:$G$25,0)),"")} | D8: {=IFERROR(INDEX('My Debts'!$E$16:$E$25,MATCH($A8,'My Debts'!$G$16:$G$25,0)),"")} | E8: {=IFERROR(INDEX('My Debts'!$F$16:$F$25,MATCH($A8,'My Debts'!$G$16:$G$25,0)),"")} | F8: {=IFERROR(INDEX('My Debts'!$H$16:$H$25,MATCH($A8,'My Debts'!$G$16:$G$25,0)),"")} | G8: =IF($B8="","",IF($A8=1,"🎯 ATTACK THIS FIRST: pay the minimum + all your extra payment here.","Pay only the minimum until it's your turn."))
A9: 4 | B9: {=IFERROR(INDEX('My Debts'!$B$16:$B$25,MATCH($A9,'My Debts'!$G$16:$G$25,0)),"")} | C9: {=IFERROR(INDEX('My Debts'!$D$16:$D$25,MATCH($A9,'My Debts'!$G$16:$G$25,0)),"")} | D9: {=IFERROR(INDEX('My Debts'!$E$16:$E$25,MATCH($A9,'My Debts'!$G$16:$G$25,0)),"")} | E9: {=IFERROR(INDEX('My Debts'!$F$16:$F$25,MATCH($A9,'My Debts'!$G$16:$G$25,0)),"")} | F9: {=IFERROR(INDEX('My Debts'!$H$16:$H$25,MATCH($A9,'My Debts'!$G$16:$G$25,0)),"")} | G9: =IF($B9="","",IF($A9=1,"🎯 ATTACK THIS FIRST: pay the minimum + all your extra payment here.","Pay only the minimum until it's your turn."))
A10: 5 | B10: {=IFERROR(INDEX('My Debts'!$B$16:$B$25,MATCH($A10,'My Debts'!$G$16:$G$25,0)),"")} | C10: {=IFERROR(INDEX('My Debts'!$D$16:$D$25,MATCH($A10,'My Debts'!$G$16:$G$25,0)),"")} | D10: {=IFERROR(INDEX('My Debts'!$E$16:$E$25,MATCH($A10,'My Debts'!$G$16:$G$25,0)),"")} | E10: {=IFERROR(INDEX('My Debts'!$F$16:$F$25,MATCH($A10,'My Debts'!$G$16:$G$25,0)),"")} | F10: {=IFERROR(INDEX('My Debts'!$H$16:$H$25,MATCH($A10,'My Debts'!$G$16:$G$25,0)),"")} | G10: =IF($B10="","",IF($A10=1,"🎯 ATTACK THIS FIRST: pay the minimum + all your extra payment here.","Pay only the minimum until it's your turn."))
A11: 6 | B11: {=IFERROR(INDEX('My Debts'!$B$16:$B$25,MATCH($A11,'My Debts'!$G$16:$G$25,0)),"")} | C11: {=IFERROR(INDEX('My Debts'!$D$16:$D$25,MATCH($A11,'My Debts'!$G$16:$G$25,0)),"")} | D11: {=IFERROR(INDEX('My Debts'!$E$16:$E$25,MATCH($A11,'My Debts'!$G$16:$G$25,0)),"")} | E11: {=IFERROR(INDEX('My Debts'!$F$16:$F$25,MATCH($A11,'My Debts'!$G$16:$G$25,0)),"")} | F11: {=IFERROR(INDEX('My Debts'!$H$16:$H$25,MATCH($A11,'My Debts'!$G$16:$G$25,0)),"")} | G11: =IF($B11="","",IF($A11=1,"🎯 ATTACK THIS FIRST: pay the minimum + all your extra payment here.","Pay only the minimum until it's your turn."))
A12: 7 | B12: {=IFERROR(INDEX('My Debts'!$B$16:$B$25,MATCH($A12,'My Debts'!$G$16:$G$25,0)),"")} | C12: {=IFERROR(INDEX('My Debts'!$D$16:$D$25,MATCH($A12,'My Debts'!$G$16:$G$25,0)),"")} | D12: {=IFERROR(INDEX('My Debts'!$E$16:$E$25,MATCH($A12,'My Debts'!$G$16:$G$25,0)),"")} | E12: {=IFERROR(INDEX('My Debts'!$F$16:$F$25,MATCH($A12,'My Debts'!$G$16:$G$25,0)),"")} | F12: {=IFERROR(INDEX('My Debts'!$H$16:$H$25,MATCH($A12,'My Debts'!$G$16:$G$25,0)),"")} | G12: =IF($B12="","",IF($A12=1,"🎯 ATTACK THIS FIRST: pay the minimum + all your extra payment here.","Pay only the minimum until it's your turn."))
A13: 8 | B13: {=IFERROR(INDEX('My Debts'!$B$16:$B$25,MATCH($A13,'My Debts'!$G$16:$G$25,0)),"")} | C13: {=IFERROR(INDEX('My Debts'!$D$16:$D$25,MATCH($A13,'My Debts'!$G$16:$G$25,0)),"")} | D13: {=IFERROR(INDEX('My Debts'!$E$16:$E$25,MATCH($A13,'My Debts'!$G$16:$G$25,0)),"")} | E13: {=IFERROR(INDEX('My Debts'!$F$16:$F$25,MATCH($A13,'My Debts'!$G$16:$G$25,0)),"")} | F13: {=IFERROR(INDEX('My Debts'!$H$16:$H$25,MATCH($A13,'My Debts'!$G$16:$G$25,0)),"")} | G13: =IF($B13="","",IF($A13=1,"🎯 ATTACK THIS FIRST: pay the minimum + all your extra payment here.","Pay only the minimum until it's your turn."))
A14: 9 | B14: {=IFERROR(INDEX('My Debts'!$B$16:$B$25,MATCH($A14,'My Debts'!$G$16:$G$25,0)),"")} | C14: {=IFERROR(INDEX('My Debts'!$D$16:$D$25,MATCH($A14,'My Debts'!$G$16:$G$25,0)),"")} | D14: {=IFERROR(INDEX('My Debts'!$E$16:$E$25,MATCH($A14,'My Debts'!$G$16:$G$25,0)),"")} | E14: {=IFERROR(INDEX('My Debts'!$F$16:$F$25,MATCH($A14,'My Debts'!$G$16:$G$25,0)),"")} | F14: {=IFERROR(INDEX('My Debts'!$H$16:$H$25,MATCH($A14,'My Debts'!$G$16:$G$25,0)),"")} | G14: =IF($B14="","",IF($A14=1,"🎯 ATTACK THIS FIRST: pay the minimum + all your extra payment here.","Pay only the minimum until it's your turn."))
A15: 10 | B15: {=IFERROR(INDEX('My Debts'!$B$16:$B$25,MATCH($A15,'My Debts'!$G$16:$G$25,0)),"")} | C15: {=IFERROR(INDEX('My Debts'!$D$16:$D$25,MATCH($A15,'My Debts'!$G$16:$G$25,0)),"")} | D15: {=IFERROR(INDEX('My Debts'!$E$16:$E$25,MATCH($A15,'My Debts'!$G$16:$G$25,0)),"")} | E15: {=IFERROR(INDEX('My Debts'!$F$16:$F$25,MATCH($A15,'My Debts'!$G$16:$G$25,0)),"")} | F15: {=IFERROR(INDEX('My Debts'!$H$16:$H$25,MATCH($A15,'My Debts'!$G$16:$G$25,0)),"")} | G15: =IF($B15="","",IF($A15=1,"🎯 ATTACK THIS FIRST: pay the minimum + all your extra payment here.","Pay only the minimum until it's your turn."))

Sheet Payment Schedule
A1: Payment Schedule — month-by-month simulation (snowball method)
A2: Monthly rate | C2: {=IFERROR(INDEX('My Debts'!$E$16:$E$25,MATCH(1,'My Debts'!$G$16:$G$25,0))/12,0)} | D2: {=IFERROR(INDEX('My Debts'!$E$16:$E$25,MATCH(2,'My Debts'!$G$16:$G$25,0))/12,0)} | E2: {=IFERROR(INDEX('My Debts'!$E$16:$E$25,MATCH(3,'My Debts'!$G$16:$G$25,0))/12,0)} | F2: {=IFERROR(INDEX('My Debts'!$E$16:$E$25,MATCH(4,'My Debts'!$G$16:$G$25,0))/12,0)} | G2: {=IFERROR(INDEX('My Debts'!$E$16:$E$25,MATCH(5,'My Debts'!$G$16:$G$25,0))/12,0)} | H2: {=IFERROR(INDEX('My Debts'!$E$16:$E$25,MATCH(6,'My Debts'!$G$16:$G$25,0))/12,0)} | I2: {=IFERROR(INDEX('My Debts'!$E$16:$E$25,MATCH(7,'My Debts'!$G$16:$G$25,0))/12,0)} | J2: {=IFERROR(INDEX('My Debts'!$E$16:$E$25,MATCH(8,'My Debts'!$G$16:$G$25,0))/12,0)} | K2: {=IFERROR(INDEX('My Debts'!$E$16:$E$25,MATCH(9,'My Debts'!$G$16:$G$25,0))/12,0)} | L2: {=IFERROR(INDEX('My Debts'!$E$16:$E$25,MATCH(10,'My Debts'!$G$16:$G$25,0))/12,0)}
A3: Parameters | C3: {=IFERROR(INDEX('My Debts'!$D$16:$D$25,MATCH(1,'My Debts'!$G$16:$G$25,0)),0)} | D3: {=IFERROR(INDEX('My Debts'!$D$16:$D$25,MATCH(2,'My Debts'!$G$16:$G$25,0)),0)} | E3: {=IFERROR(INDEX('My Debts'!$D$16:$D$25,MATCH(3,'My Debts'!$G$16:$G$25,0)),0)} | F3: {=IFERROR(INDEX('My Debts'!$D$16:$D$25,MATCH(4,'My Debts'!$G$16:$G$25,0)),0)} | G3: {=IFERROR(INDEX('My Debts'!$D$16:$D$25,MATCH(5,'My Debts'!$G$16:$G$25,0)),0)} | H3: {=IFERROR(INDEX('My Debts'!$D$16:$D$25,MATCH(6,'My Debts'!$G$16:$G$25,0)),0)} | I3: {=IFERROR(INDEX('My Debts'!$D$16:$D$25,MATCH(7,'My Debts'!$G$16:$G$25,0)),0)} | J3: {=IFERROR(INDEX('My Debts'!$D$16:$D$25,MATCH(8,'My Debts'!$G$16:$G$25,0)),0)} | K3: {=IFERROR(INDEX('My Debts'!$D$16:$D$25,MATCH(9,'My Debts'!$G$16:$G$25,0)),0)} | L3: {=IFERROR(INDEX('My Debts'!$D$16:$D$25,MATCH(10,'My Debts'!$G$16:$G$25,0)),0)} | M3: {=IFERROR(INDEX('My Debts'!$F$16:$F$25,MATCH(1,'My Debts'!$G$16:$G$25,0)),0)} | N3: {=IFERROR(INDEX('My Debts'!$F$16:$F$25,MATCH(2,'My Debts'!$G$16:$G$25,0)),0)} | O3: {=IFERROR(INDEX('My Debts'!$F$16:$F$25,MATCH(3,'My Debts'!$G$16:$G$25,0)),0)} | P3: {=IFERROR(INDEX('My Debts'!$F$16:$F$25,MATCH(4,'My Debts'!$G$16:$G$25,0)),0)} | Q3: {=IFERROR(INDEX('My Debts'!$F$16:$F$25,MATCH(5,'My Debts'!$G$16:$G$25,0)),0)} | R3: {=IFERROR(INDEX('My Debts'!$F$16:$F$25,MATCH(6,'My Debts'!$G$16:$G$25,0)),0)} | S3: {=IFERROR(INDEX('My Debts'!$F$16:$F$25,MATCH(7,'My Debts'!$G$16:$G$25,0)),0)} | T3: {=IFERROR(INDEX('My Debts'!$F$16:$F$25,MATCH(8,'My Debts'!$G$16:$G$25,0)),0)} | U3: {=IFERROR(INDEX('My Debts'!$F$16:$F$25,MATCH(9,'My Debts'!$G$16:$G$25,0)),0)} | V3: {=IFERROR(INDEX('My Debts'!$F$16:$F$25,MATCH(10,'My Debts'!$G$16:$G$25,0)),0)}
A4: Month | B4: Total payment for the month | C4: {="Saldo: "&IFERROR(INDEX('My Debts'!$B$16:$B$25,MATCH(1,'My Debts'!$G$16:$G$25,0)),"—")} | D4: {="Saldo: "&IFERROR(INDEX('My Debts'!$B$16:$B$25,MATCH(2,'My Debts'!$G$16:$G$25,0)),"—")} | E4: {="Saldo: "&IFERROR(INDEX('My Debts'!$B$16:$B$25,MATCH(3,'My Debts'!$G$16:$G$25,0)),"—")} | F4: {="Saldo: "&IFERROR(INDEX('My Debts'!$B$16:$B$25,MATCH(4,'My Debts'!$G$16:$G$25,0)),"—")} | G4: {="Saldo: "&IFERROR(INDEX('My Debts'!$B$16:$B$25,MATCH(5,'My Debts'!$G$16:$G$25,0)),"—")} | H4: {="Saldo: "&IFERROR(INDEX('My Debts'!$B$16:$B$25,MATCH(6,'My Debts'!$G$16:$G$25,0)),"—")} | I4: {="Saldo: "&IFERROR(INDEX('My Debts'!$B$16:$B$25,MATCH(7,'My Debts'!$G$16:$G$25,0)),"—")} | J4: {="Saldo: "&IFERROR(INDEX('My Debts'!$B$16:$B$25,MATCH(8,'My Debts'!$G$16:$G$25,0)),"—")} | K4: {="Saldo: "&IFERROR(INDEX('My Debts'!$B$16:$B$25,MATCH(9,'My Debts'!$G$16:$G$25,0)),"—")} | L4: {="Saldo: "&IFERROR(INDEX('My Debts'!$B$16:$B$25,MATCH(10,'My Debts'!$G$16:$G$25,0)),"—")} | M4: {="Pago: "&IFERROR(INDEX('My Debts'!$B$16:$B$25,MATCH(1,'My Debts'!$G$16:$G$25,0)),"—")} | N4: {="Pago: "&IFERROR(INDEX('My Debts'!$B$16:$B$25,MATCH(2,'My Debts'!$G$16:$G$25,0)),"—")} | O4: {="Pago: "&IFERROR(INDEX('My Debts'!$B$16:$B$25,MATCH(3,'My Debts'!$G$16:$G$25,0)),"—")} | P4: {="Pago: "&IFERROR(INDEX('My Debts'!$B$16:$B$25,MATCH(4,'My Debts'!$G$16:$G$25,0)),"—")} | Q4: {="Pago: "&IFERROR(INDEX('My Debts'!$B$16:$B$25,MATCH(5,'My Debts'!$G$16:$G$25,0)),"—")} | R4: {="Pago: "&IFERROR(INDEX('My Debts'!$B$16:$B$25,MATCH(6,'My Debts'!$G$16:$G$25,0)),"—")} | S4: {="Pago: "&IFERROR(INDEX('My Debts'!$B$16:$B$25,MATCH(7,'My Debts'!$G$16:$G$25,0)),"—")} | T4: {="Pago: "&IFERROR(INDEX('My Debts'!$B$16:$B$25,MATCH(8,'My Debts'!$G$16:$G$25,0)),"—")} | U4: {="Pago: "&IFERROR(INDEX('My Debts'!$B$16:$B$25,MATCH(9,'My Debts'!$G$16:$G$25,0)),"—")} | V4: {="Pago: "&IFERROR(INDEX('My Debts'!$B$16:$B$25,MATCH(10,'My Debts'!$G$16:$G$25,0)),"—")} | W4: Interest for the month | X4: Total debt | Y4: Focus
A5: 0 | B5: 0 | C5: =C3 | D5: =D3 | E5: =E3 | F5: =F3 | G5: =G3 | H5: =H3 | I5: =I3 | J5: =J3 | ... L5: =L3 | M5: 0 | N5: 0 | O5: 0 | P5: 0 | Q5: 0 | R5: 0 | S5: 0 | T5: 0 | U5: 0 | V5: 0 | W5: 0 | X5: =SUM(C5:L5)
A6: 1 | B6: =IF($X5>0,'My Debts'!$B$8,0) | C6: =ROUND(MAX(0,$C5*(1+C$2)-M6),2) | D6: =ROUND(MAX(0,$D5*(1+D$2)-N6),2) | E6: =ROUND(MAX(0,$E5*(1+E$2)-O6),2) | F6: =ROUND(MAX(0,$F5*(1+F$2)-P6),2) | G6: =ROUND(MAX(0,$G5*(1+G$2)-Q6),2) | H6: =ROUND(MAX(0,$H5*(1+H$2)-R6),2) | I6: =ROUND(MAX(0,$I5*(1+I$2)-S6),2) | J6: =ROUND(MAX(0,$J5*(1+J$2)-T6),2) | K6: =ROUND(MAX(0,$K5*(1+K$2)-U6),2) | L6: =ROUND(MAX(0,$L5*(1+L$2)-V6),2) | M6: =IF($C5<=0,0,IF($Y6=1,MIN($C5*(1+C$2),MAX(0,$B6-(IF($D5>0,MIN($N$3,$D5*(1+$D$2)),0)+IF($E5>0,MIN($O$3,$E5*(1+$E$2)),0)+IF($F5>0,MIN($P$3,$F5*(1+$F$2)),0)+IF($G5>0,MIN($Q$3,$G5*(1+$G$2)),0)+IF($H5>0,MIN($R$3,$H5*(1+$H$2)),0)+IF($I5>0,MIN($S$3,$I5*(1+$I$2)),0)+IF($J5>0,MIN($T$3,$J5*(1+$J$2)),0)+IF($K5>0,MIN($U$3,$K5*(1+$K$2)),0)+IF($L5>0,MIN($V$3,$L5*(1+$L$2)),0)))),MIN($M$3,$C5*(1+C$2)))) | N6: =IF($D5<=0,0,IF($Y6=2,MIN($D5*(1+D$2),MAX(0,$B6-(IF($C5>0,MIN($M$3,$C5*(1+$C$2)),0)+IF($E5>0,MIN($O$3,$E5*(1+$E$2)),0)+IF($F5>0,MIN($P$3,$F5*(1+$F$2)),0)+IF($G5>0,MIN($Q$3,$G5*(1+$G$2)),0)+IF($H5>0,MIN($R$3,$H5*(1+$H$2)),0)+IF($I5>0,MIN($S$3,$I5*(1+$I$2)),0)+IF($J5>0,MIN($T$3,$J5*(1+$J$2)),0)+IF($K5>0,MIN($U$3,$K5*(1+$K$2)),0)+IF($L5>0,MIN($V$3,$L5*(1+$L$2)),0)))),MIN($N$3,$D5*(1+D$2)))) | O6: =IF($E5<=0,0,IF($Y6=3,MIN($E5*(1+E$2),MAX(0,$B6-(IF($C5>0,MIN($M$3,$C5*(1+$C$2)),0)+IF($D5>0,MIN($N$3,$D5*(1+$D$2)),0)+IF($F5>0,MIN($P$3,$F5*(1+$F$2)),0)+IF($G5>0,MIN($Q$3,$G5*(1+$G$2)),0)+IF($H5>0,MIN($R$3,$H5*(1+$H$2)),0)+IF($I5>0,MIN($S$3,$I5*(1+$I$2)),0)+IF($J5>0,MIN($T$3,$J5*(1+$J$2)),0)+IF($K5>0,MIN($U$3,$K5*(1+$K$2)),0)+IF($L5>0,MIN($V$3,$L5*(1+$L$2)),0)))),MIN($O$3,$E5*(1+E$2)))) | P6: =IF($F5<=0,0,IF($Y6=4,MIN($F5*(1+F$2),MAX(0,$B6-(IF($C5>0,MIN($M$3,$C5*(1+$C$2)),0)+IF($D5>0,MIN($N$3,$D5*(1+$D$2)),0)+IF($E5>0,MIN($O$3,$E5*(1+$E$2)),0)+IF($G5>0,MIN($Q$3,$G5*(1+$G$2)),0)+IF($H5>0,MIN($R$3,$H5*(1+$H$2)),0)+IF($I5>0,MIN($S$3,$I5*(1+$I$2)),0)+IF($J5>0,MIN($T$3,$J5*(1+$J$2)),0)+IF($K5>0,MIN($U$3,$K5*(1+$K$2)),0)+IF($L5>0,MIN($V$3,$L5*(1+$L$2)),0)))),MIN($P$3,$F5*(1+F$2)))) | Q6: =IF($G5<=0,0,IF($Y6=5,MIN($G5*(1+G$2),MAX(0,$B6-(IF($C5>0,MIN($M$3,$C5*(1+$C$2)),0)+IF($D5>0,MIN($N$3,$D5*(1+$D$2)),0)+IF($E5>0,MIN($O$3,$E5*(1+$E$2)),0)+IF($F5>0,MIN($P$3,$F5*(1+$F$2)),0)+IF($H5>0,MIN($R$3,$H5*(1+$H$2)),0)+IF($I5>0,MIN($S$3,$I5*(1+$I$2)),0)+IF($J5>0,MIN($T$3,$J5*(1+$J$2)),0)+IF($K5>0,MIN($U$3,$K5*(1+$K$2)),0)+IF($L5>0,MIN($V$3,$L5*(1+$L$2)),0)))),MIN($Q$3,$G5*(1+G$2)))) | R6: =IF($H5<=0,0,IF($Y6=6,MIN($H5*(1+H$2),MAX(0,$B6-(IF($C5>0,MIN($M$3,$C5*(1+$C$2)),0)+IF($D5>0,MIN($N$3,$D5*(1+$D$2)),0)+IF($E5>0,MIN($O$3,$E5*(1+$E$2)),0)+IF($F5>0,MIN($P$3,$F5*(1+$F$2)),0)+IF($G5>0,MIN($Q$3,$G5*(1+$G$2)),0)+IF($I5>0,MIN($S$3,$I5*(1+$I$2)),0)+IF($J5>0,MIN($T$3,$J5*(1+$J$2)),0)+IF($K5>0,MIN($U$3,$K5*(1+$K$2)),0)+IF($L5>0,MIN($V$3,$L5*(1+$L$2)),0)))),MIN($R$3,$H5*(1+H$2)))) | S6: =IF($I5<=0,0,IF($Y6=7,MIN($I5*(1+I$2),MAX(0,$B6-(IF($C5>0,MIN($M$3,$C5*(1+$C$2)),0)+IF($D5>0,MIN($N$3,$D5*(1+$D$2)),0)+IF($E5>0,MIN($O$3,$E5*(1+$E$2)),0)+IF($F5>0,MIN($P$3,$F5*(1+$F$2)),0)+IF($G5>0,MIN($Q$3,$G5*(1+$G$2)),0)+IF($H5>0,MIN($R$3,$H5*(1+$H$2)),0)+IF($J5>0,MIN($T$3,$J5*(1+$J$2)),0)+IF($K5>0,MIN($U$3,$K5*(1+$K$2)),0)+IF($L5>0,MIN($V$3,$L5*(1+$L$2)),0)))),MIN($S$3,$I5*(1+I$2)))) | T6: =IF($J5<=0,0,IF($Y6=8,MIN($J5*(1+J$2),MAX(0,$B6-(IF($C5>0,MIN($M$3,$C5*(1+$C$2)),0)+IF($D5>0,MIN($N$3,$D5*(1+$D$2)),0)+IF($E5>0,MIN($O$3,$E5*(1+$E$2)),0)+IF($F5>0,MIN($P$3,$F5*(1+$F$2)),0)+IF($G5>0,MIN($Q$3,$G5*(1+$G$2)),0)+IF($H5>0,MIN($R$3,$H5*(1+$H$2)),0)+IF($I5>0,MIN($S$3,$I5*(1+$I$2)),0)+IF($K5>0,MIN($U$3,$K5*(1+$K$2)),0)+IF($L5>0,MIN($V$3,$L5*(1+$L$2)),0)))),MIN($T$3,$J5*(1+J$2)))) | U6: =IF($K5<=0,0,IF($Y6=9,MIN($K5*(1+K$2),MAX(0,$B6-(IF($C5>0,MIN($M$3,$C5*(1+$C$2)),0)+IF($D5>0,MIN($N$3,$D5*(1+$D$2)),0)+IF($E5>0,MIN($O$3,$E5*(1+$E$2)),0)+IF($F5>0,MIN($P$3,$F5*(1+$F$2)),0)+IF($G5>0,MIN($Q$3,$G5*(1+$G$2)),0)+IF($H5>0,MIN($R$3,$H5*(1+$H$2)),0)+IF($I5>0,MIN($S$3,$I5*(1+$I$2)),0)+IF($J5>0,MIN($T$3,$J5*(1+$J$2)),0)+IF($L5>0,MIN($V$3,$L5*(1+$L$2)),0)))),MIN($U$3,$K5*(1+K$2)))) | V6: =IF($L5<=0,0,IF($Y6=10,MIN($L5*(1+L$2),MAX(0,$B6-(IF($C5>0,MIN($M$3,$C5*(1+$C$2)),0)+IF($D5>0,MIN($N$3,$D5*(1+$D$2)),0)+IF($E5>0,MIN($O$3,$E5*(1+$E$2)),0)+IF($F5>0,MIN($P$3,$F5*(1+$F$2)),0)+IF($G5>0,MIN($Q$3,$G5*(1+$G$2)),0)+IF($H5>0,MIN($R$3,$H5*(1+$H$2)),0)+IF($I5>0,MIN($S$3,$I5*(1+$I$2)),0)+IF($J5>0,MIN($T$3,$J5*(1+$J$2)),0)+IF($K5>0,MIN($U$3,$K5*(1+$K$2)),0)))),MIN($V$3,$L5*(1+L$2)))) | W6: =ROUND(SUMPRODUCT($C5:$L5,$C$2:$L$2),2) | X6: =SUM($C6:$L6) | Y6: =IF($X5=0,"",MIN(IF($C5>0,1,'My Debts'!$B$13+1),IF($D5>0,2,'My Debts'!$B$13+1),IF($E5>0,3,'My Debts'!$B$13+1),IF($F5>0,4,'My Debts'!$B$13+1),IF($G5>0,5,'My Debts'!$B$13+1),IF($H5>0,6,'My Debts'!$B$13+1),IF($I5>0,7,'My Debts'!$B$13+1),IF($J5>0,8,'My Debts'!$B$13+1),IF($K5>0,9,'My Debts'!$B$13+1),IF($L5>0,10,'My Debts'!$B$13+1)))
A7: 2 | B7: =IF($X6>0,'My Debts'!$B$8,0) | C7: =ROUND(MAX(0,$C6*(1+C$2)-M7),2) | D7: =ROUND(MAX(0,$D6*(1+D$2)-N7),2) | E7: =ROUND(MAX(0,$E6*(1+E$2)-O7),2) | F7: =ROUND(MAX(0,$F6*(1+F$2)-P7),2) | G7: =ROUND(MAX(0,$G6*(1+G$2)-Q7),2) | H7: =ROUND(MAX(0,$H6*(1+H$2)-R7),2) | I7: =ROUND(MAX(0,$I6*(1+I$2)-S7),2) | J7: =ROUND(MAX(0,$J6*(1+J$2)-T7),2) | K7: =ROUND(MAX(0,$K6*(1+K$2)-U7),2) | L7: =ROUND(MAX(0,$L6*(1+L$2)-V7),2) | M7: =IF($C6<=0,0,IF($Y7=1,MIN($C6*(1+C$2),MAX(0,$B7-(IF($D6>0,MIN($N$3,$D6*(1+$D$2)),0)+IF($E6>0,MIN($O$3,$E6*(1+$E$2)),0)+IF($F6>0,MIN($P$3,$F6*(1+$F$2)),0)+IF($G6>0,MIN($Q$3,$G6*(1+$G$2)),0)+IF($H6>0,MIN($R$3,$H6*(1+$H$2)),0)+IF($I6>0,MIN($S$3,$I6*(1+$I$2)),0)+IF($J6>0,MIN($T$3,$J6*(1+$J$2)),0)+IF($K6>0,MIN($U$3,$K6*(1+$K$2)),0)+IF($L6>0,MIN($V$3,$L6*(1+$L$2)),0)))),MIN($M$3,$C6*(1+C$2)))) | N7: =IF($D6<=0,0,IF($Y7=2,MIN($D6*(1+D$2),MAX(0,$B7-(IF($C6>0,MIN($M$3,$C6*(1+$C$2)),0)+IF($E6>0,MIN($O$3,$E6*(1+$E$2)),0)+IF($F6>0,MIN($P$3,$F6*(1+$F$2)),0)+IF($G6>0,MIN($Q$3,$G6*(1+$G$2)),0)+IF($H6>0,MIN($R$3,$H6*(1+$H$2)),0)+IF($I6>0,MIN($S$3,$I6*(1+$I$2)),0)+IF($J6>0,MIN($T$3,$J6*(1+$J$2)),0)+IF($K6>0,MIN($U$3,$K6*(1+$K$2)),0)+IF($L6>0,MIN($V$3,$L6*(1+$L$2)),0)))),MIN($N$3,$D6*(1+D$2)))) | O7: =IF($E6<=0,0,IF($Y7=3,MIN($E6*(1+E$2),MAX(0,$B7-(IF($C6>0,MIN($M$3,$C6*(1+$C$2)),0)+IF($D6>0,MIN($N$3,$D6*(1+$D$2)),0)+IF($F6>0,MIN($P$3,$F6*(1+$F$2)),0)+IF($G6>0,MIN($Q$3,$G6*(1+$G$2)),0)+IF($H6>0,MIN($R$3,$H6*(1+$H$2)),0)+IF($I6>0,MIN($S$3,$I6*(1+$I$2)),0)+IF($J6>0,MIN($T$3,$J6*(1+$J$2)),0)+IF($K6>0,MIN($U$3,$K6*(1+$K$2)),0)+IF($L6>0,MIN($V$3,$L6*(1+$L$2)),0)))),MIN($O$3,$E6*(1+E$2)))) | P7: =IF($F6<=0,0,IF($Y7=4,MIN($F6*(1+F$2),MAX(0,$B7-(IF($C6>0,MIN($M$3,$C6*(1+$C$2)),0)+IF($D6>0,MIN($N$3,$D6*(1+$D$2)),0)+IF($E6>0,MIN($O$3,$E6*(1+$E$2)),0)+IF($G6>0,MIN($Q$3,$G6*(1+$G$2)),0)+IF($H6>0,MIN($R$3,$H6*(1+$H$2)),0)+IF($I6>0,MIN($S$3,$I6*(1+$I$2)),0)+IF($J6>0,MIN($T$3,$J6*(1+$J$2)),0)+IF($K6>0,MIN($U$3,$K6*(1+$K$2)),0)+IF($L6>0,MIN($V$3,$L6*(1+$L$2)),0)))),MIN($P$3,$F6*(1+F$2)))) | Q7: =IF($G6<=0,0,IF($Y7=5,MIN($G6*(1+G$2),MAX(0,$B7-(IF($C6>0,MIN($M$3,$C6*(1+$C$2)),0)+IF($D6>0,MIN($N$3,$D6*(1+$D$2)),0)+IF($E6>0,MIN($O$3,$E6*(1+$E$2)),0)+IF($F6>0,MIN($P$3,$F6*(1+$F$2)),0)+IF($H6>0,MIN($R$3,$H6*(1+$H$2)),0)+IF($I6>0,MIN($S$3,$I6*(1+$I$2)),0)+IF($J6>0,MIN($T$3,$J6*(1+$J$2)),0)+IF($K6>0,MIN($U$3,$K6*(1+$K$2)),0)+IF($L6>0,MIN($V$3,$L6*(1+$L$2)),0)))),MIN($Q$3,$G6*(1+G$2)))) | R7: =IF($H6<=0,0,IF($Y7=6,MIN($H6*(1+H$2),MAX(0,$B7-(IF($C6>0,MIN($M$3,$C6*(1+$C$2)),0)+IF($D6>0,MIN($N$3,$D6*(1+$D$2)),0)+IF($E6>0,MIN($O$3,$E6*(1+$E$2)),0)+IF($F6>0,MIN($P$3,$F6*(1+$F$2)),0)+IF($G6>0,MIN($Q$3,$G6*(1+$G$2)),0)+IF($I6>0,MIN($S$3,$I6*(1+$I$2)),0)+IF($J6>0,MIN($T$3,$J6*(1+$J$2)),0)+IF($K6>0,MIN($U$3,$K6*(1+$K$2)),0)+IF($L6>0,MIN($V$3,$L6*(1+$L$2)),0)))),MIN($R$3,$H6*(1+H$2)))) | S7: =IF($I6<=0,0,IF($Y7=7,MIN($I6*(1+I$2),MAX(0,$B7-(IF($C6>0,MIN($M$3,$C6*(1+$C$2)),0)+IF($D6>0,MIN($N$3,$D6*(1+$D$2)),0)+IF($E6>0,MIN($O$3,$E6*(1+$E$2)),0)+IF($F6>0,MIN($P$3,$F6*(1+$F$2)),0)+IF($G6>0,MIN($Q$3,$G6*(1+$G$2)),0)+IF($H6>0,MIN($R$3,$H6*(1+$H$2)),0)+IF($J6>0,MIN($T$3,$J6*(1+$J$2)),0)+IF($K6>0,MIN($U$3,$K6*(1+$K$2)),0)+IF($L6>0,MIN($V$3,$L6*(1+$L$2)),0)))),MIN($S$3,$I6*(1+I$2)))) | T7: =IF($J6<=0,0,IF($Y7=8,MIN($J6*(1+J$2),MAX(0,$B7-(IF($C6>0,MIN($M$3,$C6*(1+$C$2)),0)+IF($D6>0,MIN($N$3,$D6*(1+$D$2)),0)+IF($E6>0,MIN($O$3,$E6*(1+$E$2)),0)+IF($F6>0,MIN($P$3,$F6*(1+$F$2)),0)+IF($G6>0,MIN($Q$3,$G6*(1+$G$2)),0)+IF($H6>0,MIN($R$3,$H6*(1+$H$2)),0)+IF($I6>0,MIN($S$3,$I6*(1+$I$2)),0)+IF($K6>0,MIN($U$3,$K6*(1+$K$2)),0)+IF($L6>0,MIN($V$3,$L6*(1+$L$2)),0)))),MIN($T$3,$J6*(1+J$2)))) | U7: =IF($K6<=0,0,IF($Y7=9,MIN($K6*(1+K$2),MAX(0,$B7-(IF($C6>0,MIN($M$3,$C6*(1+$C$2)),0)+IF($D6>0,MIN($N$3,$D6*(1+$D$2)),0)+IF($E6>0,MIN($O$3,$E6*(1+$E$2)),0)+IF($F6>0,MIN($P$3,$F6*(1+$F$2)),0)+IF($G6>0,MIN($Q$3,$G6*(1+$G$2)),0)+IF($H6>0,MIN($R$3,$H6*(1+$H$2)),0)+IF($I6>0,MIN($S$3,$I6*(1+$I$2)),0)+IF($J6>0,MIN($T$3,$J6*(1+$J$2)),0)+IF($L6>0,MIN($V$3,$L6*(1+$L$2)),0)))),MIN($U$3,$K6*(1+K$2)))) | V7: =IF($L6<=0,0,IF($Y7=10,MIN($L6*(1+L$2),MAX(0,$B7-(IF($C6>0,MIN($M$3,$C6*(1+$C$2)),0)+IF($D6>0,MIN($N$3,$D6*(1+$D$2)),0)+IF($E6>0,MIN($O$3,$E6*(1+$E$2)),0)+IF($F6>0,MIN($P$3,$F6*(1+$F$2)),0)+IF($G6>0,MIN($Q$3,$G6*(1+$G$2)),0)+IF($H6>0,MIN($R$3,$H6*(1+$H$2)),0)+IF($I6>0,MIN($S$3,$I6*(1+$I$2)),0)+IF($J6>0,MIN($T$3,$J6*(1+$J$2)),0)+IF($K6>0,MIN($U$3,$K6*(1+$K$2)),0)))),MIN($V$3,$L6*(1+L$2)))) | W7: =ROUND(SUMPRODUCT($C6:$L6,$C$2:$L$2),2) | X7: =SUM($C7:$L7) | Y7: =IF($X6=0,"",MIN(IF($C6>0,1,'My Debts'!$B$13+1),IF($D6>0,2,'My Debts'!$B$13+1),IF($E6>0,3,'My Debts'!$B$13+1),IF($F6>0,4,'My Debts'!$B$13+1),IF($G6>0,5,'My Debts'!$B$13+1),IF($H6>0,6,'My Debts'!$B$13+1),IF($I6>0,7,'My Debts'!$B$13+1),IF($J6>0,8,'My Debts'!$B$13+1),IF($K6>0,9,'My Debts'!$B$13+1),IF($L6>0,10,'My Debts'!$B$13+1)))
A8: 3 | B8: =IF($X7>0,'My Debts'!$B$8,0) | C8: =ROUND(MAX(0,$C7*(1+C$2)-M8),2) | D8: =ROUND(MAX(0,$D7*(1+D$2)-N8),2) | E8: =ROUND(MAX(0,$E7*(1+E$2)-O8),2) | F8: =ROUND(MAX(0,$F7*(1+F$2)-P8),2) | G8: =ROUND(MAX(0,$G7*(1+G$2)-Q8),2) | H8: =ROUND(MAX(0,$H7*(1+H$2)-R8),2) | I8: =ROUND(MAX(0,$I7*(1+I$2)-S8),2) | J8: =ROUND(MAX(0,$J7*(1+J$2)-T8),2) | K8: =ROUND(MAX(0,$K7*(1+K$2)-U8),2) | L8: =ROUND(MAX(0,$L7*(1+L$2)-V8),2) | M8: =IF($C7<=0,0,IF($Y8=1,MIN($C7*(1+C$2),MAX(0,$B8-(IF($D7>0,MIN($N$3,$D7*(1+$D$2)),0)+IF($E7>0,MIN($O$3,$E7*(1+$E$2)),0)+IF($F7>0,MIN($P$3,$F7*(1+$F$2)),0)+IF($G7>0,MIN($Q$3,$G7*(1+$G$2)),0)+IF($H7>0,MIN($R$3,$H7*(1+$H$2)),0)+IF($I7>0,MIN($S$3,$I7*(1+$I$2)),0)+IF($J7>0,MIN($T$3,$J7*(1+$J$2)),0)+IF($K7>0,MIN($U$3,$K7*(1+$K$2)),0)+IF($L7>0,MIN($V$3,$L7*(1+$L$2)),0)))),MIN($M$3,$C7*(1+C$2)))) | N8: =IF($D7<=0,0,IF($Y8=2,MIN($D7*(1+D$2),MAX(0,$B8-(IF($C7>0,MIN($M$3,$C7*(1+$C$2)),0)+IF($E7>0,MIN($O$3,$E7*(1+$E$2)),0)+IF($F7>0,MIN($P$3,$F7*(1+$F$2)),0)+IF($G7>0,MIN($Q$3,$G7*(1+$G$2)),0)+IF($H7>0,MIN($R$3,$H7*(1+$H$2)),0)+IF($I7>0,MIN($S$3,$I7*(1+$I$2)),0)+IF($J7>0,MIN($T$3,$J7*(1+$J$2)),0)+IF($K7>0,MIN($U$3,$K7*(1+$K$2)),0)+IF($L7>0,MIN($V$3,$L7*(1+$L$2)),0)))),MIN($N$3,$D7*(1+D$2)))) | O8: =IF($E7<=0,0,IF($Y8=3,MIN($E7*(1+E$2),MAX(0,$B8-(IF($C7>0,MIN($M$3,$C7*(1+$C$2)),0)+IF($D7>0,MIN($N$3,$D7*(1+$D$2)),0)+IF($F7>0,MIN($P$3,$F7*(1+$F$2)),0)+IF($G7>0,MIN($Q$3,$G7*(1+$G$2)),0)+IF($H7>0,MIN($R$3,$H7*(1+$H$2)),0)+IF($I7>0,MIN($S$3,$I7*(1+$I$2)),0)+IF($J7>0,MIN($T$3,$J7*(1+$J$2)),0)+IF($K7>0,MIN($U$3,$K7*(1+$K$2)),0)+IF($L7>0,MIN($V$3,$L7*(1+$L$2)),0)))),MIN($O$3,$E7*(1+E$2)))) | P8: =IF($F7<=0,0,IF($Y8=4,MIN($F7*(1+F$2),MAX(0,$B8-(IF($C7>0,MIN($M$3,$C7*(1+$C$2)),0)+IF($D7>0,MIN($N$3,$D7*(1+$D$2)),0)+IF($E7>0,MIN($O$3,$E7*(1+$E$2)),0)+IF($G7>0,MIN($Q$3,$G7*(1+$G$2)),0)+IF($H7>0,MIN($R$3,$H7*(1+$H$2)),0)+IF($I7>0,MIN($S$3,$I7*(1+$I$2)),0)+IF($J7>0,MIN($T$3,$J7*(1+$J$2)),0)+IF($K7>0,MIN($U$3,$K7*(1+$K$2)),0)+IF($L7>0,MIN($V$3,$L7*(1+$L$2)),0)))),MIN($P$3,$F7*(1+F$2)))) | Q8: =IF($G7<=0,0,IF($Y8=5,MIN($G7*(1+G$2),MAX(0,$B8-(IF($C7>0,MIN($M$3,$C7*(1+$C$2)),0)+IF($D7>0,MIN($N$3,$D7*(1+$D$2)),0)+IF($E7>0,MIN($O$3,$E7*(1+$E$2)),0)+IF($F7>0,MIN($P$3,$F7*(1+$F$2)),0)+IF($H7>0,MIN($R$3,$H7*(1+$H$2)),0)+IF($I7>0,MIN($S$3,$I7*(1+$I$2)),0)+IF($J7>0,MIN($T$3,$J7*(1+$J$2)),0)+IF($K7>0,MIN($U$3,$K7*(1+$K$2)),0)+IF($L7>0,MIN($V$3,$L7*(1+$L$2)),0)))),MIN($Q$3,$G7*(1+G$2)))) | R8: =IF($H7<=0,0,IF($Y8=6,MIN($H7*(1+H$2),MAX(0,$B8-(IF($C7>0,MIN($M$3,$C7*(1+$C$2)),0)+IF($D7>0,MIN($N$3,$D7*(1+$D$2)),0)+IF($E7>0,MIN($O$3,$E7*(1+$E$2)),0)+IF($F7>0,MIN($P$3,$F7*(1+$F$2)),0)+IF($G7>0,MIN($Q$3,$G7*(1+$G$2)),0)+IF($I7>0,MIN($S$3,$I7*(1+$I$2)),0)+IF($J7>0,MIN($T$3,$J7*(1+$J$2)),0)+IF($K7>0,MIN($U$3,$K7*(1+$K$2)),0)+IF($L7>0,MIN($V$3,$L7*(1+$L$2)),0)))),MIN($R$3,$H7*(1+H$2)))) | S8: =IF($I7<=0,0,IF($Y8=7,MIN($I7*(1+I$2),MAX(0,$B8-(IF($C7>0,MIN($M$3,$C7*(1+$C$2)),0)+IF($D7>0,MIN($N$3,$D7*(1+$D$2)),0)+IF($E7>0,MIN($O$3,$E7*(1+$E$2)),0)+IF($F7>0,MIN($P$3,$F7*(1+$F$2)),0)+IF($G7>0,MIN($Q$3,$G7*(1+$G$2)),0)+IF($H7>0,MIN($R$3,$H7*(1+$H$2)),0)+IF($J7>0,MIN($T$3,$J7*(1+$J$2)),0)+IF($K7>0,MIN($U$3,$K7*(1+$K$2)),0)+IF($L7>0,MIN($V$3,$L7*(1+$L$2)),0)))),MIN($S$3,$I7*(1+I$2)))) | T8: =IF($J7<=0,0,IF($Y8=8,MIN($J7*(1+J$2),MAX(0,$B8-(IF($C7>0,MIN($M$3,$C7*(1+$C$2)),0)+IF($D7>0,MIN($N$3,$D7*(1+$D$2)),0)+IF($E7>0,MIN($O$3,$E7*(1+$E$2)),0)+IF($F7>0,MIN($P$3,$F7*(1+$F$2)),0)+IF($G7>0,MIN($Q$3,$G7*(1+$G$2)),0)+IF($H7>0,MIN($R$3,$H7*(1+$H$2)),0)+IF($I7>0,MIN($S$3,$I7*(1+$I$2)),0)+IF($K7>0,MIN($U$3,$K7*(1+$K$2)),0)+IF($L7>0,MIN($V$3,$L7*(1+$L$2)),0)))),MIN($T$3,$J7*(1+J$2)))) | U8: =IF($K7<=0,0,IF($Y8=9,MIN($K7*(1+K$2),MAX(0,$B8-(IF($C7>0,MIN($M$3,$C7*(1+$C$2)),0)+IF($D7>0,MIN($N$3,$D7*(1+$D$2)),0)+IF($E7>0,MIN($O$3,$E7*(1+$E$2)),0)+IF($F7>0,MIN($P$3,$F7*(1+$F$2)),0)+IF($G7>0,MIN($Q$3,$G7*(1+$G$2)),0)+IF($H7>0,MIN($R$3,$H7*(1+$H$2)),0)+IF($I7>0,MIN($S$3,$I7*(1+$I$2)),0)+IF($J7>0,MIN($T$3,$J7*(1+$J$2)),0)+IF($L7>0,MIN($V$3,$L7*(1+$L$2)),0)))),MIN($U$3,$K7*(1+K$2)))) | V8: =IF($L7<=0,0,IF($Y8=10,MIN($L7*(1+L$2),MAX(0,$B8-(IF($C7>0,MIN($M$3,$C7*(1+$C$2)),0)+IF($D7>0,MIN($N$3,$D7*(1+$D$2)),0)+IF($E7>0,MIN($O$3,$E7*(1+$E$2)),0)+IF($F7>0,MIN($P$3,$F7*(1+$F$2)),0)+IF($G7>0,MIN($Q$3,$G7*(1+$G$2)),0)+IF($H7>0,MIN($R$3,$H7*(1+$H$2)),0)+IF($I7>0,MIN($S$3,$I7*(1+$I$2)),0)+IF($J7>0,MIN($T$3,$J7*(1+$J$2)),0)+IF($K7>0,MIN($U$3,$K7*(1+$K$2)),0)))),MIN($V$3,$L7*(1+L$2)))) | W8: =ROUND(SUMPRODUCT($C7:$L7,$C$2:$L$2),2) | X8: =SUM($C8:$L8) | Y8: =IF($X7=0,"",MIN(IF($C7>0,1,'My Debts'!$B$13+1),IF($D7>0,2,'My Debts'!$B$13+1),IF($E7>0,3,'My Debts'!$B$13+1),IF($F7>0,4,'My Debts'!$B$13+1),IF($G7>0,5,'My Debts'!$B$13+1),IF($H7>0,6,'My Debts'!$B$13+1),IF($I7>0,7,'My Debts'!$B$13+1),IF($J7>0,8,'My Debts'!$B$13+1),IF($K7>0,9,'My Debts'!$B$13+1),IF($L7>0,10,'My Debts'!$B$13+1)))
A9: 4 | B9: =IF($X8>0,'My Debts'!$B$8,0) | C9: =ROUND(MAX(0,$C8*(1+C$2)-M9),2) | D9: =ROUND(MAX(0,$D8*(1+D$2)-N9),2) | E9: =ROUND(MAX(0,$E8*(1+E$2)-O9),2) | F9: =ROUND(MAX(0,$F8*(1+F$2)-P9),2) | G9: =ROUND(MAX(0,$G8*(1+G$2)-Q9),2) | H9: =ROUND(MAX(0,$H8*(1+H$2)-R9),2) | I9: =ROUND(MAX(0,$I8*(1+I$2)-S9),2) | J9: =ROUND(MAX(0,$J8*(1+J$2)-T9),2) | K9: =ROUND(MAX(0,$K8*(1+K$2)-U9),2) | L9: =ROUND(MAX(0,$L8*(1+L$2)-V9),2) | M9: =IF($C8<=0,0,IF($Y9=1,MIN($C8*(1+C$2),MAX(0,$B9-(IF($D8>0,MIN($N$3,$D8*(1+$D$2)),0)+IF($E8>0,MIN($O$3,$E8*(1+$E$2)),0)+IF($F8>0,MIN($P$3,$F8*(1+$F$2)),0)+IF($G8>0,MIN($Q$3,$G8*(1+$G$2)),0)+IF($H8>0,MIN($R$3,$H8*(1+$H$2)),0)+IF($I8>0,MIN($S$3,$I8*(1+$I$2)),0)+IF($J8>0,MIN($T$3,$J8*(1+$J$2)),0)+IF($K8>0,MIN($U$3,$K8*(1+$K$2)),0)+IF($L8>0,MIN($V$3,$L8*(1+$L$2)),0)))),MIN($M$3,$C8*(1+C$2)))) | N9: =IF($D8<=0,0,IF($Y9=2,MIN($D8*(1+D$2),MAX(0,$B9-(IF($C8>0,MIN($M$3,$C8*(1+$C$2)),0)+IF($E8>0,MIN($O$3,$E8*(1+$E$2)),0)+IF($F8>0,MIN($P$3,$F8*(1+$F$2)),0)+IF($G8>0,MIN($Q$3,$G8*(1+$G$2)),0)+IF($H8>0,MIN($R$3,$H8*(1+$H$2)),0)+IF($I8>0,MIN($S$3,$I8*(1+$I$2)),0)+IF($J8>0,MIN($T$3,$J8*(1+$J$2)),0)+IF($K8>0,MIN($U$3,$K8*(1+$K$2)),0)+IF($L8>0,MIN($V$3,$L8*(1+$L$2)),0)))),MIN($N$3,$D8*(1+D$2)))) | O9: =IF($E8<=0,0,IF($Y9=3,MIN($E8*(1+E$2),MAX(0,$B9-(IF($C8>0,MIN($M$3,$C8*(1+$C$2)),0)+IF($D8>0,MIN($N$3,$D8*(1+$D$2)),0)+IF($F8>0,MIN($P$3,$F8*(1+$F$2)),0)+IF($G8>0,MIN($Q$3,$G8*(1+$G$2)),0)+IF($H8>0,MIN($R$3,$H8*(1+$H$2)),0)+IF($I8>0,MIN($S$3,$I8*(1+$I$2)),0)+IF($J8>0,MIN($T$3,$J8*(1+$J$2)),0)+IF($K8>0,MIN($U$3,$K8*(1+$K$2)),0)+IF($L8>0,MIN($V$3,$L8*(1+$L$2)),0)))),MIN($O$3,$E8*(1+E$2)))) | P9: =IF($F8<=0,0,IF($Y9=4,MIN($F8*(1+F$2),MAX(0,$B9-(IF($C8>0,MIN($M$3,$C8*(1+$C$2)),0)+IF($D8>0,MIN($N$3,$D8*(1+$D$2)),0)+IF($E8>0,MIN($O$3,$E8*(1+$E$2)),0)+IF($G8>0,MIN($Q$3,$G8*(1+$G$2)),0)+IF($H8>0,MIN($R$3,$H8*(1+$H$2)),0)+IF($I8>0,MIN($S$3,$I8*(1+$I$2)),0)+IF($J8>0,MIN($T$3,$J8*(1+$J$2)),0)+IF($K8>0,MIN($U$3,$K8*(1+$K$2)),0)+IF($L8>0,MIN($V$3,$L8*(1+$L$2)),0)))),MIN($P$3,$F8*(1+F$2)))) | Q9: =IF($G8<=0,0,IF($Y9=5,MIN($G8*(1+G$2),MAX(0,$B9-(IF($C8>0,MIN($M$3,$C8*(1+$C$2)),0)+IF($D8>0,MIN($N$3,$D8*(1+$D$2)),0)+IF($E8>0,MIN($O$3,$E8*(1+$E$2)),0)+IF($F8>0,MIN($P$3,$F8*(1+$F$2)),0)+IF($H8>0,MIN($R$3,$H8*(1+$H$2)),0)+IF($I8>0,MIN($S$3,$I8*(1+$I$2)),0)+IF($J8>0,MIN($T$3,$J8*(1+$J$2)),0)+IF($K8>0,MIN($U$3,$K8*(1+$K$2)),0)+IF($L8>0,MIN($V$3,$L8*(1+$L$2)),0)))),MIN($Q$3,$G8*(1+G$2)))) | R9: =IF($H8<=0,0,IF($Y9=6,MIN($H8*(1+H$2),MAX(0,$B9-(IF($C8>0,MIN($M$3,$C8*(1+$C$2)),0)+IF($D8>0,MIN($N$3,$D8*(1+$D$2)),0)+IF($E8>0,MIN($O$3,$E8*(1+$E$2)),0)+IF($F8>0,MIN($P$3,$F8*(1+$F$2)),0)+IF($G8>0,MIN($Q$3,$G8*(1+$G$2)),0)+IF($I8>0,MIN($S$3,$I8*(1+$I$2)),0)+IF($J8>0,MIN($T$3,$J8*(1+$J$2)),0)+IF($K8>0,MIN($U$3,$K8*(1+$K$2)),0)+IF($L8>0,MIN($V$3,$L8*(1+$L$2)),0)))),MIN($R$3,$H8*(1+H$2)))) | S9: =IF($I8<=0,0,IF($Y9=7,MIN($I8*(1+I$2),MAX(0,$B9-(IF($C8>0,MIN($M$3,$C8*(1+$C$2)),0)+IF($D8>0,MIN($N$3,$D8*(1+$D$2)),0)+IF($E8>0,MIN($O$3,$E8*(1+$E$2)),0)+IF($F8>0,MIN($P$3,$F8*(1+$F$2)),0)+IF($G8>0,MIN($Q$3,$G8*(1+$G$2)),0)+IF($H8>0,MIN($R$3,$H8*(1+$H$2)),0)+IF($J8>0,MIN($T$3,$J8*(1+$J$2)),0)+IF($K8>0,MIN($U$3,$K8*(1+$K$2)),0)+IF($L8>0,MIN($V$3,$L8*(1+$L$2)),0)))),MIN($S$3,$I8*(1+I$2)))) | T9: =IF($J8<=0,0,IF($Y9=8,MIN($J8*(1+J$2),MAX(0,$B9-(IF($C8>0,MIN($M$3,$C8*(1+$C$2)),0)+IF($D8>0,MIN($N$3,$D8*(1+$D$2)),0)+IF($E8>0,MIN($O$3,$E8*(1+$E$2)),0)+IF($F8>0,MIN($P$3,$F8*(1+$F$2)),0)+IF($G8>0,MIN($Q$3,$G8*(1+$G$2)),0)+IF($H8>0,MIN($R$3,$H8*(1+$H$2)),0)+IF($I8>0,MIN($S$3,$I8*(1+$I$2)),0)+IF($K8>0,MIN($U$3,$K8*(1+$K$2)),0)+IF($L8>0,MIN($V$3,$L8*(1+$L$2)),0)))),MIN($T$3,$J8*(1+J$2)))) | U9: =IF($K8<=0,0,IF($Y9=9,MIN($K8*(1+K$2),MAX(0,$B9-(IF($C8>0,MIN($M$3,$C8*(1+$C$2)),0)+IF($D8>0,MIN($N$3,$D8*(1+$D$2)),0)+IF($E8>0,MIN($O$3,$E8*(1+$E$2)),0)+IF($F8>0,MIN($P$3,$F8*(1+$F$2)),0)+IF($G8>0,MIN($Q$3,$G8*(1+$G$2)),0)+IF($H8>0,MIN($R$3,$H8*(1+$H$2)),0)+IF($I8>0,MIN($S$3,$I8*(1+$I$2)),0)+IF($J8>0,MIN($T$3,$J8*(1+$J$2)),0)+IF($L8>0,MIN($V$3,$L8*(1+$L$2)),0)))),MIN($U$3,$K8*(1+K$2)))) | V9: =IF($L8<=0,0,IF($Y9=10,MIN($L8*(1+L$2),MAX(0,$B9-(IF($C8>0,MIN($M$3,$C8*(1+$C$2)),0)+IF($D8>0,MIN($N$3,$D8*(1+$D$2)),0)+IF($E8>0,MIN($O$3,$E8*(1+$E$2)),0)+IF($F8>0,MIN($P$3,$F8*(1+$F$2)),0)+IF($G8>0,MIN($Q$3,$G8*(1+$G$2)),0)+IF($H8>0,MIN($R$3,$H8*(1+$H$2)),0)+IF($I8>0,MIN($S$3,$I8*(1+$I$2)),0)+IF($J8>0,MIN($T$3,$J8*(1+$J$2)),0)+IF($K8>0,MIN($U$3,$K8*(1+$K$2)),0)))),MIN($V$3,$L8*(1+L$2)))) | W9: =ROUND(SUMPRODUCT($C8:$L8,$C$2:$L$2),2) | X9: =SUM($C9:$L9) | Y9: =IF($X8=0,"",MIN(IF($C8>0,1,'My Debts'!$B$13+1),IF($D8>0,2,'My Debts'!$B$13+1),IF($E8>0,3,'My Debts'!$B$13+1),IF($F8>0,4,'My Debts'!$B$13+1),IF($G8>0,5,'My Debts'!$B$13+1),IF($H8>0,6,'My Debts'!$B$13+1),IF($I8>0,7,'My Debts'!$B$13+1),IF($J8>0,8,'My Debts'!$B$13+1),IF($K8>0,9,'My Debts'!$B$13+1),IF($L8>0,10,'My Debts'!$B$13+1)))
A10: 5 | B10: =IF($X9>0,'My Debts'!$B$8,0) | C10: =ROUND(MAX(0,$C9*(1+C$2)-M10),2) | D10: =ROUND(MAX(0,$D9*(1+D$2)-N10),2) | E10: =ROUND(MAX(0,$E9*(1+E$2)-O10),2) | F10: =ROUND(MAX(0,$F9*(1+F$2)-P10),2) | G10: =ROUND(MAX(0,$G9*(1+G$2)-Q10),2) | H10: =ROUND(MAX(0,$H9*(1+H$2)-R10),2) | I10: =ROUND(MAX(0,$I9*(1+I$2)-S10),2) | J10: =ROUND(MAX(0,$J9*(1+J$2)-T10),2) | K10: =ROUND(MAX(0,$K9*(1+K$2)-U10),2) | L10: =ROUND(MAX(0,$L9*(1+L$2)-V10),2) | M10: =IF($C9<=0,0,IF($Y10=1,MIN($C9*(1+C$2),MAX(0,$B10-(IF($D9>0,MIN($N$3,$D9*(1+$D$2)),0)+IF($E9>0,MIN($O$3,$E9*(1+$E$2)),0)+IF($F9>0,MIN($P$3,$F9*(1+$F$2)),0)+IF($G9>0,MIN($Q$3,$G9*(1+$G$2)),0)+IF($H9>0,MIN($R$3,$H9*(1+$H$2)),0)+IF($I9>0,MIN($S$3,$I9*(1+$I$2)),0)+IF($J9>0,MIN($T$3,$J9*(1+$J$2)),0)+IF($K9>0,MIN($U$3,$K9*(1+$K$2)),0)+IF($L9>0,MIN($V$3,$L9*(1+$L$2)),0)))),MIN($M$3,$C9*(1+C$2)))) | N10: =IF($D9<=0,0,IF($Y10=2,MIN($D9*(1+D$2),MAX(0,$B10-(IF($C9>0,MIN($M$3,$C9*(1+$C$2)),0)+IF($E9>0,MIN($O$3,$E9*(1+$E$2)),0)+IF($F9>0,MIN($P$3,$F9*(1+$F$2)),0)+IF($G9>0,MIN($Q$3,$G9*(1+$G$2)),0)+IF($H9>0,MIN($R$3,$H9*(1+$H$2)),0)+IF($I9>0,MIN($S$3,$I9*(1+$I$2)),0)+IF($J9>0,MIN($T$3,$J9*(1+$J$2)),0)+IF($K9>0,MIN($U$3,$K9*(1+$K$2)),0)+IF($L9>0,MIN($V$3,$L9*(1+$L$2)),0)))),MIN($N$3,$D9*(1+D$2)))) | O10: =IF($E9<=0,0,IF($Y10=3,MIN($E9*(1+E$2),MAX(0,$B10-(IF($C9>0,MIN($M$3,$C9*(1+$C$2)),0)+IF($D9>0,MIN($N$3,$D9*(1+$D$2)),0)+IF($F9>0,MIN($P$3,$F9*(1+$F$2)),0)+IF($G9>0,MIN($Q$3,$G9*(1+$G$2)),0)+IF($H9>0,MIN($R$3,$H9*(1+$H$2)),0)+IF($I9>0,MIN($S$3,$I9*(1+$I$2)),0)+IF($J9>0,MIN($T$3,$J9*(1+$J$2)),0)+IF($K9>0,MIN($U$3,$K9*(1+$K$2)),0)+IF($L9>0,MIN($V$3,$L9*(1+$L$2)),0)))),MIN($O$3,$E9*(1+E$2)))) | P10: =IF($F9<=0,0,IF($Y10=4,MIN($F9*(1+F$2),MAX(0,$B10-(IF($C9>0,MIN($M$3,$C9*(1+$C$2)),0)+IF($D9>0,MIN($N$3,$D9*(1+$D$2)),0)+IF($E9>0,MIN($O$3,$E9*(1+$E$2)),0)+IF($G9>0,MIN($Q$3,$G9*(1+$G$2)),0)+IF($H9>0,MIN($R$3,$H9*(1+$H$2)),0)+IF($I9>0,MIN($S$3,$I9*(1+$I$2)),0)+IF($J9>0,MIN($T$3,$J9*(1+$J$2)),0)+IF($K9>0,MIN($U$3,$K9*(1+$K$2)),0)+IF($L9>0,MIN($V$3,$L9*(1+$L$2)),0)))),MIN($P$3,$F9*(1+F$2)))) | Q10: =IF($G9<=0,0,IF($Y10=5,MIN($G9*(1+G$2),MAX(0,$B10-(IF($C9>0,MIN($M$3,$C9*(1+$C$2)),0)+IF($D9>0,MIN($N$3,$D9*(1+$D$2)),0)+IF($E9>0,MIN($O$3,$E9*(1+$E$2)),0)+IF($F9>0,MIN($P$3,$F9*(1+$F$2)),0)+IF($H9>0,MIN($R$3,$H9*(1+$H$2)),0)+IF($I9>0,MIN($S$3,$I9*(1+$I$2)),0)+IF($J9>0,MIN($T$3,$J9*(1+$J$2)),0)+IF($K9>0,MIN($U$3,$K9*(1+$K$2)),0)+IF($L9>0,MIN($V$3,$L9*(1+$L$2)),0)))),MIN($Q$3,$G9*(1+G$2)))) | R10: =IF($H9<=0,0,IF($Y10=6,MIN($H9*(1+H$2),MAX(0,$B10-(IF($C9>0,MIN($M$3,$C9*(1+$C$2)),0)+IF($D9>0,MIN($N$3,$D9*(1+$D$2)),0)+IF($E9>0,MIN($O$3,$E9*(1+$E$2)),0)+IF($F9>0,MIN($P$3,$F9*(1+$F$2)),0)+IF($G9>0,MIN($Q$3,$G9*(1+$G$2)),0)+IF($I9>0,MIN($S$3,$I9*(1+$I$2)),0)+IF($J9>0,MIN($T$3,$J9*(1+$J$2)),0)+IF($K9>0,MIN($U$3,$K9*(1+$K$2)),0)+IF($L9>0,MIN($V$3,$L9*(1+$L$2)),0)))),MIN($R$3,$H9*(1+H$2)))) | S10: =IF($I9<=0,0,IF($Y10=7,MIN($I9*(1+I$2),MAX(0,$B10-(IF($C9>0,MIN($M$3,$C9*(1+$C$2)),0)+IF($D9>0,MIN($N$3,$D9*(1+$D$2)),0)+IF($E9>0,MIN($O$3,$E9*(1+$E$2)),0)+IF($F9>0,MIN($P$3,$F9*(1+$F$2)),0)+IF($G9>0,MIN($Q$3,$G9*(1+$G$2)),0)+IF($H9>0,MIN($R$3,$H9*(1+$H$2)),0)+IF($J9>0,MIN($T$3,$J9*(1+$J$2)),0)+IF($K9>0,MIN($U$3,$K9*(1+$K$2)),0)+IF($L9>0,MIN($V$3,$L9*(1+$L$2)),0)))),MIN($S$3,$I9*(1+I$2)))) | T10: =IF($J9<=0,0,IF($Y10=8,MIN($J9*(1+J$2),MAX(0,$B10-(IF($C9>0,MIN($M$3,$C9*(1+$C$2)),0)+IF($D9>0,MIN($N$3,$D9*(1+$D$2)),0)+IF($E9>0,MIN($O$3,$E9*(1+$E$2)),0)+IF($F9>0,MIN($P$3,$F9*(1+$F$2)),0)+IF($G9>0,MIN($Q$3,$G9*(1+$G$2)),0)+IF($H9>0,MIN($R$3,$H9*(1+$H$2)),0)+IF($I9>0,MIN($S$3,$I9*(1+$I$2)),0)+IF($K9>0,MIN($U$3,$K9*(1+$K$2)),0)+IF($L9>0,MIN($V$3,$L9*(1+$L$2)),0)))),MIN($T$3,$J9*(1+J$2)))) | U10: =IF($K9<=0,0,IF($Y10=9,MIN($K9*(1+K$2),MAX(0,$B10-(IF($C9>0,MIN($M$3,$C9*(1+$C$2)),0)+IF($D9>0,MIN($N$3,$D9*(1+$D$2)),0)+IF($E9>0,MIN($O$3,$E9*(1+$E$2)),0)+IF($F9>0,MIN($P$3,$F9*(1+$F$2)),0)+IF($G9>0,MIN($Q$3,$G9*(1+$G$2)),0)+IF($H9>0,MIN($R$3,$H9*(1+$H$2)),0)+IF($I9>0,MIN($S$3,$I9*(1+$I$2)),0)+IF($J9>0,MIN($T$3,$J9*(1+$J$2)),0)+IF($L9>0,MIN($V$3,$L9*(1+$L$2)),0)))),MIN($U$3,$K9*(1+K$2)))) | V10: =IF($L9<=0,0,IF($Y10=10,MIN($L9*(1+L$2),MAX(0,$B10-(IF($C9>0,MIN($M$3,$C9*(1+$C$2)),0)+IF($D9>0,MIN($N$3,$D9*(1+$D$2)),0)+IF($E9>0,MIN($O$3,$E9*(1+$E$2)),0)+IF($F9>0,MIN($P$3,$F9*(1+$F$2)),0)+IF($G9>0,MIN($Q$3,$G9*(1+$G$2)),0)+IF($H9>0,MIN($R$3,$H9*(1+$H$2)),0)+IF($I9>0,MIN($S$3,$I9*(1+$I$2)),0)+IF($J9>0,MIN($T$3,$J9*(1+$J$2)),0)+IF($K9>0,MIN($U$3,$K9*(1+$K$2)),0)))),MIN($V$3,$L9*(1+L$2)))) | W10: =ROUND(SUMPRODUCT($C9:$L9,$C$2:$L$2),2) | X10: =SUM($C10:$L10) | Y10: =IF($X9=0,"",MIN(IF($C9>0,1,'My Debts'!$B$13+1),IF($D9>0,2,'My Debts'!$B$13+1),IF($E9>0,3,'My Debts'!$B$13+1),IF($F9>0,4,'My Debts'!$B$13+1),IF($G9>0,5,'My Debts'!$B$13+1),IF($H9>0,6,'My Debts'!$B$13+1),IF($I9>0,7,'My Debts'!$B$13+1),IF($J9>0,8,'My Debts'!$B$13+1),IF($K9>0,9,'My Debts'!$B$13+1),IF($L9>0,10,'My Debts'!$B$13+1)))
A11: 6 | B11: =IF($X10>0,'My Debts'!$B$8,0) | C11: =ROUND(MAX(0,$C10*(1+C$2)-M11),2) | D11: =ROUND(MAX(0,$D10*(1+D$2)-N11),2) | E11: =ROUND(MAX(0,$E10*(1+E$2)-O11),2) | F11: =ROUND(MAX(0,$F10*(1+F$2)-P11),2) | G11: =ROUND(MAX(0,$G10*(1+G$2)-Q11),2) | H11: =ROUND(MAX(0,$H10*(1+H$2)-R11),2) | I11: =ROUND(MAX(0,$I10*(1+I$2)-S11),2) | J11: =ROUND(MAX(0,$J10*(1+J$2)-T11),2) | K11: =ROUND(MAX(0,$K10*(1+K$2)-U11),2) | L11: =ROUND(MAX(0,$L10*(1+L$2)-V11),2) | M11: =IF($C10<=0,0,IF($Y11=1,MIN($C10*(1+C$2),MAX(0,$B11-(IF($D10>0,MIN($N$3,$D10*(1+$D$2)),0)+IF($E10>0,MIN($O$3,$E10*(1+$E$2)),0)+IF($F10>0,MIN($P$3,$F10*(1+$F$2)),0)+IF($G10>0,MIN($Q$3,$G10*(1+$G$2)),0)+IF($H10>0,MIN($R$3,$H10*(1+$H$2)),0)+IF($I10>0,MIN($S$3,$I10*(1+$I$2)),0)+IF($J10>0,MIN($T$3,$J10*(1+$J$2)),0)+IF($K10>0,MIN($U$3,$K10*(1+$K$2)),0)+IF($L10>0,MIN($V$3,$L10*(1+$L$2)),0)))),MIN($M$3,$C10*(1+C$2)))) | N11: =IF($D10<=0,0,IF($Y11=2,MIN($D10*(1+D$2),MAX(0,$B11-(IF($C10>0,MIN($M$3,$C10*(1+$C$2)),0)+IF($E10>0,MIN($O$3,$E10*(1+$E$2)),0)+IF($F10>0,MIN($P$3,$F10*(1+$F$2)),0)+IF($G10>0,MIN($Q$3,$G10*(1+$G$2)),0)+IF($H10>0,MIN($R$3,$H10*(1+$H$2)),0)+IF($I10>0,MIN($S$3,$I10*(1+$I$2)),0)+IF($J10>0,MIN($T$3,$J10*(1+$J$2)),0)+IF($K10>0,MIN($U$3,$K10*(1+$K$2)),0)+IF($L10>0,MIN($V$3,$L10*(1+$L$2)),0)))),MIN($N$3,$D10*(1+D$2)))) | O11: =IF($E10<=0,0,IF($Y11=3,MIN($E10*(1+E$2),MAX(0,$B11-(IF($C10>0,MIN($M$3,$C10*(1+$C$2)),0)+IF($D10>0,MIN($N$3,$D10*(1+$D$2)),0)+IF($F10>0,MIN($P$3,$F10*(1+$F$2)),0)+IF($G10>0,MIN($Q$3,$G10*(1+$G$2)),0)+IF($H10>0,MIN($R$3,$H10*(1+$H$2)),0)+IF($I10>0,MIN($S$3,$I10*(1+$I$2)),0)+IF($J10>0,MIN($T$3,$J10*(1+$J$2)),0)+IF($K10>0,MIN($U$3,$K10*(1+$K$2)),0)+IF($L10>0,MIN($V$3,$L10*(1+$L$2)),0)))),MIN($O$3,$E10*(1+E$2)))) | P11: =IF($F10<=0,0,IF($Y11=4,MIN($F10*(1+F$2),MAX(0,$B11-(IF($C10>0,MIN($M$3,$C10*(1+$C$2)),0)+IF($D10>0,MIN($N$3,$D10*(1+$D$2)),0)+IF($E10>0,MIN($O$3,$E10*(1+$E$2)),0)+IF($G10>0,MIN($Q$3,$G10*(1+$G$2)),0)+IF($H10>0,MIN($R$3,$H10*(1+$H$2)),0)+IF($I10>0,MIN($S$3,$I10*(1+$I$2)),0)+IF($J10>0,MIN($T$3,$J10*(1+$J$2)),0)+IF($K10>0,MIN($U$3,$K10*(1+$K$2)),0)+IF($L10>0,MIN($V$3,$L10*(1+$L$2)),0)))),MIN($P$3,$F10*(1+F$2)))) | Q11: =IF($G10<=0,0,IF($Y11=5,MIN($G10*(1+G$2),MAX(0,$B11-(IF($C10>0,MIN($M$3,$C10*(1+$C$2)),0)+IF($D10>0,MIN($N$3,$D10*(1+$D$2)),0)+IF($E10>0,MIN($O$3,$E10*(1+$E$2)),0)+IF($F10>0,MIN($P$3,$F10*(1+$F$2)),0)+IF($H10>0,MIN($R$3,$H10*(1+$H$2)),0)+IF($I10>0,MIN($S$3,$I10*(1+$I$2)),0)+IF($J10>0,MIN($T$3,$J10*(1+$J$2)),0)+IF($K10>0,MIN($U$3,$K10*(1+$K$2)),0)+IF($L10>0,MIN($V$3,$L10*(1+$L$2)),0)))),MIN($Q$3,$G10*(1+G$2)))) | R11: =IF($H10<=0,0,IF($Y11=6,MIN($H10*(1+H$2),MAX(0,$B11-(IF($C10>0,MIN($M$3,$C10*(1+$C$2)),0)+IF($D10>0,MIN($N$3,$D10*(1+$D$2)),0)+IF($E10>0,MIN($O$3,$E10*(1+$E$2)),0)+IF($F10>0,MIN($P$3,$F10*(1+$F$2)),0)+IF($G10>0,MIN($Q$3,$G10*(1+$G$2)),0)+IF($I10>0,MIN($S$3,$I10*(1+$I$2)),0)+IF($J10>0,MIN($T$3,$J10*(1+$J$2)),0)+IF($K10>0,MIN($U$3,$K10*(1+$K$2)),0)+IF($L10>0,MIN($V$3,$L10*(1+$L$2)),0)))),MIN($R$3,$H10*(1+H$2)))) | S11: =IF($I10<=0,0,IF($Y11=7,MIN($I10*(1+I$2),MAX(0,$B11-(IF($C10>0,MIN($M$3,$C10*(1+$C$2)),0)+IF($D10>0,MIN($N$3,$D10*(1+$D$2)),0)+IF($E10>0,MIN($O$3,$E10*(1+$E$2)),0)+IF($F10>0,MIN($P$3,$F10*(1+$F$2)),0)+IF($G10>0,MIN($Q$3,$G10*(1+$G$2)),0)+IF($H10>0,MIN($R$3,$H10*(1+$H$2)),0)+IF($J10>0,MIN($T$3,$J10*(1+$J$2)),0)+IF($K10>0,MIN($U$3,$K10*(1+$K$2)),0)+IF($L10>0,MIN($V$3,$L10*(1+$L$2)),0)))),MIN($S$3,$I10*(1+I$2)))) | T11: =IF($J10<=0,0,IF($Y11=8,MIN($J10*(1+J$2),MAX(0,$B11-(IF($C10>0,MIN($M$3,$C10*(1+$C$2)),0)+IF($D10>0,MIN($N$3,$D10*(1+$D$2)),0)+IF($E10>0,MIN($O$3,$E10*(1+$E$2)),0)+IF($F10>0,MIN($P$3,$F10*(1+$F$2)),0)+IF($G10>0,MIN($Q$3,$G10*(1+$G$2)),0)+IF($H10>0,MIN($R$3,$H10*(1+$H$2)),0)+IF($I10>0,MIN($S$3,$I10*(1+$I$2)),0)+IF($K10>0,MIN($U$3,$K10*(1+$K$2)),0)+IF($L10>0,MIN($V$3,$L10*(1+$L$2)),0)))),MIN($T$3,$J10*(1+J$2)))) | U11: =IF($K10<=0,0,IF($Y11=9,MIN($K10*(1+K$2),MAX(0,$B11-(IF($C10>0,MIN($M$3,$C10*(1+$C$2)),0)+IF($D10>0,MIN($N$3,$D10*(1+$D$2)),0)+IF($E10>0,MIN($O$3,$E10*(1+$E$2)),0)+IF($F10>0,MIN($P$3,$F10*(1+$F$2)),0)+IF($G10>0,MIN($Q$3,$G10*(1+$G$2)),0)+IF($H10>0,MIN($R$3,$H10*(1+$H$2)),0)+IF($I10>0,MIN($S$3,$I10*(1+$I$2)),0)+IF($J10>0,MIN($T$3,$J10*(1+$J$2)),0)+IF($L10>0,MIN($V$3,$L10*(1+$L$2)),0)))),MIN($U$3,$K10*(1+K$2)))) | V11: =IF($L10<=0,0,IF($Y11=10,MIN($L10*(1+L$2),MAX(0,$B11-(IF($C10>0,MIN($M$3,$C10*(1+$C$2)),0)+IF($D10>0,MIN($N$3,$D10*(1+$D$2)),0)+IF($E10>0,MIN($O$3,$E10*(1+$E$2)),0)+IF($F10>0,MIN($P$3,$F10*(1+$F$2)),0)+IF($G10>0,MIN($Q$3,$G10*(1+$G$2)),0)+IF($H10>0,MIN($R$3,$H10*(1+$H$2)),0)+IF($I10>0,MIN($S$3,$I10*(1+$I$2)),0)+IF($J10>0,MIN($T$3,$J10*(1+$J$2)),0)+IF($K10>0,MIN($U$3,$K10*(1+$K$2)),0)))),MIN($V$3,$L10*(1+L$2)))) | W11: =ROUND(SUMPRODUCT($C10:$L10,$C$2:$L$2),2) | X11: =SUM($C11:$L11) | Y11: =IF($X10=0,"",MIN(IF($C10>0,1,'My Debts'!$B$13+1),IF($D10>0,2,'My Debts'!$B$13+1),IF($E10>0,3,'My Debts'!$B$13+1),IF($F10>0,4,'My Debts'!$B$13+1),IF($G10>0,5,'My Debts'!$B$13+1),IF($H10>0,6,'My Debts'!$B$13+1),IF($I10>0,7,'My Debts'!$B$13+1),IF($J10>0,8,'My Debts'!$B$13+1),IF($K10>0,9,'My Debts'!$B$13+1),IF($L10>0,10,'My Debts'!$B$13+1)))
A12: 7 | B12: =IF($X11>0,'My Debts'!$B$8,0) | C12: =ROUND(MAX(0,$C11*(1+C$2)-M12),2) | D12: =ROUND(MAX(0,$D11*(1+D$2)-N12),2) | E12: =ROUND(MAX(0,$E11*(1+E$2)-O12),2) | F12: =ROUND(MAX(0,$F11*(1+F$2)-P12),2) | G12: =ROUND(MAX(0,$G11*(1+G$2)-Q12),2) | H12: =ROUND(MAX(0,$H11*(1+H$2)-R12),2) | I12: =ROUND(MAX(0,$I11*(1+I$2)-S12),2) | J12: =ROUND(MAX(0,$J11*(1+J$2)-T12),2) | K12: =ROUND(MAX(0,$K11*(1+K$2)-U12),2) | L12: =ROUND(MAX(0,$L11*(1+L$2)-V12),2) | M12: =IF($C11<=0,0,IF($Y12=1,MIN($C11*(1+C$2),MAX(0,$B12-(IF($D11>0,MIN($N$3,$D11*(1+$D$2)),0)+IF($E11>0,MIN($O$3,$E11*(1+$E$2)),0)+IF($F11>0,MIN($P$3,$F11*(1+$F$2)),0)+IF($G11>0,MIN($Q$3,$G11*(1+$G$2)),0)+IF($H11>0,MIN($R$3,$H11*(1+$H$2)),0)+IF($I11>0,MIN($S$3,$I11*(1+$I$2)),0)+IF($J11>0,MIN($T$3,$J11*(1+$J$2)),0)+IF($K11>0,MIN($U$3,$K11*(1+$K$2)),0)+IF($L11>0,MIN($V$3,$L11*(1+$L$2)),0)))),MIN($M$3,$C11*(1+C$2)))) | N12: =IF($D11<=0,0,IF($Y12=2,MIN($D11*(1+D$2),MAX(0,$B12-(IF($C11>0,MIN($M$3,$C11*(1+$C$2)),0)+IF($E11>0,MIN($O$3,$E11*(1+$E$2)),0)+IF($F11>0,MIN($P$3,$F11*(1+$F$2)),0)+IF($G11>0,MIN($Q$3,$G11*(1+$G$2)),0)+IF($H11>0,MIN($R$3,$H11*(1+$H$2)),0)+IF($I11>0,MIN($S$3,$I11*(1+$I$2)),0)+IF($J11>0,MIN($T$3,$J11*(1+$J$2)),0)+IF($K11>0,MIN($U$3,$K11*(1+$K$2)),0)+IF($L11>0,MIN($V$3,$L11*(1+$L$2)),0)))),MIN($N$3,$D11*(1+D$2)))) | O12: =IF($E11<=0,0,IF($Y12=3,MIN($E11*(1+E$2),MAX(0,$B12-(IF($C11>0,MIN($M$3,$C11*(1+$C$2)),0)+IF($D11>0,MIN($N$3,$D11*(1+$D$2)),0)+IF($F11>0,MIN($P$3,$F11*(1+$F$2)),0)+IF($G11>0,MIN($Q$3,$G11*(1+$G$2)),0)+IF($H11>0,MIN($R$3,$H11*(1+$H$2)),0)+IF($I11>0,MIN($S$3,$I11*(1+$I$2)),0)+IF($J11>0,MIN($T$3,$J11*(1+$J$2)),0)+IF($K11>0,MIN($U$3,$K11*(1+$K$2)),0)+IF($L11>0,MIN($V$3,$L11*(1+$L$2)),0)))),MIN($O$3,$E11*(1+E$2)))) | P12: =IF($F11<=0,0,IF($Y12=4,MIN($F11*(1+F$2),MAX(0,$B12-(IF($C11>0,MIN($M$3,$C11*(1+$C$2)),0)+IF($D11>0,MIN($N$3,$D11*(1+$D$2)),0)+IF($E11>0,MIN($O$3,$E11*(1+$E$2)),0)+IF($G11>0,MIN($Q$3,$G11*(1+$G$2)),0)+IF($H11>0,MIN($R$3,$H11*(1+$H$2)),0)+IF($I11>0,MIN($S$3,$I11*(1+$I$2)),0)+IF($J11>0,MIN($T$3,$J11*(1+$J$2)),0)+IF($K11>0,MIN($U$3,$K11*(1+$K$2)),0)+IF($L11>0,MIN($V$3,$L11*(1+$L$2)),0)))),MIN($P$3,$F11*(1+F$2)))) | Q12: =IF($G11<=0,0,IF($Y12=5,MIN($G11*(1+G$2),MAX(0,$B12-(IF($C11>0,MIN($M$3,$C11*(1+$C$2)),0)+IF($D11>0,MIN($N$3,$D11*(1+$D$2)),0)+IF($E11>0,MIN($O$3,$E11*(1+$E$2)),0)+IF($F11>0,MIN($P$3,$F11*(1+$F$2)),0)+IF($H11>0,MIN($R$3,$H11*(1+$H$2)),0)+IF($I11>0,MIN($S$3,$I11*(1+$I$2)),0)+IF($J11>0,MIN($T$3,$J11*(1+$J$2)),0)+IF($K11>0,MIN($U$3,$K11*(1+$K$2)),0)+IF($L11>0,MIN($V$3,$L11*(1+$L$2)),0)))),MIN($Q$3,$G11*(1+G$2)))) | R12: =IF($H11<=0,0,IF($Y12=6,MIN($H11*(1+H$2),MAX(0,$B12-(IF($C11>0,MIN($M$3,$C11*(1+$C$2)),0)+IF($D11>0,MIN($N$3,$D11*(1+$D$2)),0)+IF($E11>0,MIN($O$3,$E11*(1+$E$2)),0)+IF($F11>0,MIN($P$3,$F11*(1+$F$2)),0)+IF($G11>0,MIN($Q$3,$G11*(1+$G$2)),0)+IF($I11>0,MIN($S$3,$I11*(1+$I$2)),0)+IF($J11>0,MIN($T$3,$J11*(1+$J$2)),0)+IF($K11>0,MIN($U$3,$K11*(1+$K$2)),0)+IF($L11>0,MIN($V$3,$L11*(1+$L$2)),0)))),MIN($R$3,$H11*(1+H$2)))) | S12: =IF($I11<=0,0,IF($Y12=7,MIN($I11*(1+I$2),MAX(0,$B12-(IF($C11>0,MIN($M$3,$C11*(1+$C$2)),0)+IF($D11>0,MIN($N$3,$D11*(1+$D$2)),0)+IF($E11>0,MIN($O$3,$E11*(1+$E$2)),0)+IF($F11>0,MIN($P$3,$F11*(1+$F$2)),0)+IF($G11>0,MIN($Q$3,$G11*(1+$G$2)),0)+IF($H11>0,MIN($R$3,$H11*(1+$H$2)),0)+IF($J11>0,MIN($T$3,$J11*(1+$J$2)),0)+IF($K11>0,MIN($U$3,$K11*(1+$K$2)),0)+IF($L11>0,MIN($V$3,$L11*(1+$L$2)),0)))),MIN($S$3,$I11*(1+I$2)))) | T12: =IF($J11<=0,0,IF($Y12=8,MIN($J11*(1+J$2),MAX(0,$B12-(IF($C11>0,MIN($M$3,$C11*(1+$C$2)),0)+IF($D11>0,MIN($N$3,$D11*(1+$D$2)),0)+IF($E11>0,MIN($O$3,$E11*(1+$E$2)),0)+IF($F11>0,MIN($P$3,$F11*(1+$F$2)),0)+IF($G11>0,MIN($Q$3,$G11*(1+$G$2)),0)+IF($H11>0,MIN($R$3,$H11*(1+$H$2)),0)+IF($I11>0,MIN($S$3,$I11*(1+$I$2)),0)+IF($K11>0,MIN($U$3,$K11*(1+$K$2)),0)+IF($L11>0,MIN($V$3,$L11*(1+$L$2)),0)))),MIN($T$3,$J11*(1+J$2)))) | U12: =IF($K11<=0,0,IF($Y12=9,MIN($K11*(1+K$2),MAX(0,$B12-(IF($C11>0,MIN($M$3,$C11*(1+$C$2)),0)+IF($D11>0,MIN($N$3,$D11*(1+$D$2)),0)+IF($E11>0,MIN($O$3,$E11*(1+$E$2)),0)+IF($F11>0,MIN($P$3,$F11*(1+$F$2)),0)+IF($G11>0,MIN($Q$3,$G11*(1+$G$2)),0)+IF($H11>0,MIN($R$3,$H11*(1+$H$2)),0)+IF($I11>0,MIN($S$3,$I11*(1+$I$2)),0)+IF($J11>0,MIN($T$3,$J11*(1+$J$2)),0)+IF($L11>0,MIN($V$3,$L11*(1+$L$2)),0)))),MIN($U$3,$K11*(1+K$2)))) | V12: =IF($L11<=0,0,IF($Y12=10,MIN($L11*(1+L$2),MAX(0,$B12-(IF($C11>0,MIN($M$3,$C11*(1+$C$2)),0)+IF($D11>0,MIN($N$3,$D11*(1+$D$2)),0)+IF($E11>0,MIN($O$3,$E11*(1+$E$2)),0)+IF($F11>0,MIN($P$3,$F11*(1+$F$2)),0)+IF($G11>0,MIN($Q$3,$G11*(1+$G$2)),0)+IF($H11>0,MIN($R$3,$H11*(1+$H$2)),0)+IF($I11>0,MIN($S$3,$I11*(1+$I$2)),0)+IF($J11>0,MIN($T$3,$J11*(1+$J$2)),0)+IF($K11>0,MIN($U$3,$K11*(1+$K$2)),0)))),MIN($V$3,$L11*(1+L$2)))) | W12: =ROUND(SUMPRODUCT($C11:$L11,$C$2:$L$2),2) | X12: =SUM($C12:$L12) | Y12: =IF($X11=0,"",MIN(IF($C11>0,1,'My Debts'!$B$13+1),IF($D11>0,2,'My Debts'!$B$13+1),IF($E11>0,3,'My Debts'!$B$13+1),IF($F11>0,4,'My Debts'!$B$13+1),IF($G11>0,5,'My Debts'!$B$13+1),IF($H11>0,6,'My Debts'!$B$13+1),IF($I11>0,7,'My Debts'!$B$13+1),IF($J11>0,8,'My Debts'!$B$13+1),IF($K11>0,9,'My Debts'!$B$13+1),IF($L11>0,10,'My Debts'!$B$13+1)))
A13: 8 | B13: =IF($X12>0,'My Debts'!$B$8,0) | C13: =ROUND(MAX(0,$C12*(1+C$2)-M13),2) | D13: =ROUND(MAX(0,$D12*(1+D$2)-N13),2) | E13: =ROUND(MAX(0,$E12*(1+E$2)-O13),2) | F13: =ROUND(MAX(0,$F12*(1+F$2)-P13),2) | G13: =ROUND(MAX(0,$G12*(1+G$2)-Q13),2) | H13: =ROUND(MAX(0,$H12*(1+H$2)-R13),2) | I13: =ROUND(MAX(0,$I12*(1+I$2)-S13),2) | J13: =ROUND(MAX(0,$J12*(1+J$2)-T13),2) | K13: =ROUND(MAX(0,$K12*(1+K$2)-U13),2) | L13: =ROUND(MAX(0,$L12*(1+L$2)-V13),2) | M13: =IF($C12<=0,0,IF($Y13=1,MIN($C12*(1+C$2),MAX(0,$B13-(IF($D12>0,MIN($N$3,$D12*(1+$D$2)),0)+IF($E12>0,MIN($O$3,$E12*(1+$E$2)),0)+IF($F12>0,MIN($P$3,$F12*(1+$F$2)),0)+IF($G12>0,MIN($Q$3,$G12*(1+$G$2)),0)+IF($H12>0,MIN($R$3,$H12*(1+$H$2)),0)+IF($I12>0,MIN($S$3,$I12*(1+$I$2)),0)+IF($J12>0,MIN($T$3,$J12*(1+$J$2)),0)+IF($K12>0,MIN($U$3,$K12*(1+$K$2)),0)+IF($L12>0,MIN($V$3,$L12*(1+$L$2)),0)))),MIN($M$3,$C12*(1+C$2)))) | N13: =IF($D12<=0,0,IF($Y13=2,MIN($D12*(1+D$2),MAX(0,$B13-(IF($C12>0,MIN($M$3,$C12*(1+$C$2)),0)+IF($E12>0,MIN($O$3,$E12*(1+$E$2)),0)+IF($F12>0,MIN($P$3,$F12*(1+$F$2)),0)+IF($G12>0,MIN($Q$3,$G12*(1+$G$2)),0)+IF($H12>0,MIN($R$3,$H12*(1+$H$2)),0)+IF($I12>0,MIN($S$3,$I12*(1+$I$2)),0)+IF($J12>0,MIN($T$3,$J12*(1+$J$2)),0)+IF($K12>0,MIN($U$3,$K12*(1+$K$2)),0)+IF($L12>0,MIN($V$3,$L12*(1+$L$2)),0)))),MIN($N$3,$D12*(1+D$2)))) | O13: =IF($E12<=0,0,IF($Y13=3,MIN($E12*(1+E$2),MAX(0,$B13-(IF($C12>0,MIN($M$3,$C12*(1+$C$2)),0)+IF($D12>0,MIN($N$3,$D12*(1+$D$2)),0)+IF($F12>0,MIN($P$3,$F12*(1+$F$2)),0)+IF($G12>0,MIN($Q$3,$G12*(1+$G$2)),0)+IF($H12>0,MIN($R$3,$H12*(1+$H$2)),0)+IF($I12>0,MIN($S$3,$I12*(1+$I$2)),0)+IF($J12>0,MIN($T$3,$J12*(1+$J$2)),0)+IF($K12>0,MIN($U$3,$K12*(1+$K$2)),0)+IF($L12>0,MIN($V$3,$L12*(1+$L$2)),0)))),MIN($O$3,$E12*(1+E$2)))) | P13: =IF($F12<=0,0,IF($Y13=4,MIN($F12*(1+F$2),MAX(0,$B13-(IF($C12>0,MIN($M$3,$C12*(1+$C$2)),0)+IF($D12>0,MIN($N$3,$D12*(1+$D$2)),0)+IF($E12>0,MIN($O$3,$E12*(1+$E$2)),0)+IF($G12>0,MIN($Q$3,$G12*(1+$G$2)),0)+IF($H12>0,MIN($R$3,$H12*(1+$H$2)),0)+IF($I12>0,MIN($S$3,$I12*(1+$I$2)),0)+IF($J12>0,MIN($T$3,$J12*(1+$J$2)),0)+IF($K12>0,MIN($U$3,$K12*(1+$K$2)),0)+IF($L12>0,MIN($V$3,$L12*(1+$L$2)),0)))),MIN($P$3,$F12*(1+F$2)))) | Q13: =IF($G12<=0,0,IF($Y13=5,MIN($G12*(1+G$2),MAX(0,$B13-(IF($C12>0,MIN($M$3,$C12*(1+$C$2)),0)+IF($D12>0,MIN($N$3,$D12*(1+$D$2)),0)+IF($E12>0,MIN($O$3,$E12*(1+$E$2)),0)+IF($F12>0,MIN($P$3,$F12*(1+$F$2)),0)+IF($H12>0,MIN($R$3,$H12*(1+$H$2)),0)+IF($I12>0,MIN($S$3,$I12*(1+$I$2)),0)+IF($J12>0,MIN($T$3,$J12*(1+$J$2)),0)+IF($K12>0,MIN($U$3,$K12*(1+$K$2)),0)+IF($L12>0,MIN($V$3,$L12*(1+$L$2)),0)))),MIN($Q$3,$G12*(1+G$2)))) | R13: =IF($H12<=0,0,IF($Y13=6,MIN($H12*(1+H$2),MAX(0,$B13-(IF($C12>0,MIN($M$3,$C12*(1+$C$2)),0)+IF($D12>0,MIN($N$3,$D12*(1+$D$2)),0)+IF($E12>0,MIN($O$3,$E12*(1+$E$2)),0)+IF($F12>0,MIN($P$3,$F12*(1+$F$2)),0)+IF($G12>0,MIN($Q$3,$G12*(1+$G$2)),0)+IF($I12>0,MIN($S$3,$I12*(1+$I$2)),0)+IF($J12>0,MIN($T$3,$J12*(1+$J$2)),0)+IF($K12>0,MIN($U$3,$K12*(1+$K$2)),0)+IF($L12>0,MIN($V$3,$L12*(1+$L$2)),0)))),MIN($R$3,$H12*(1+H$2)))) | S13: =IF($I12<=0,0,IF($Y13=7,MIN($I12*(1+I$2),MAX(0,$B13-(IF($C12>0,MIN($M$3,$C12*(1+$C$2)),0)+IF($D12>0,MIN($N$3,$D12*(1+$D$2)),0)+IF($E12>0,MIN($O$3,$E12*(1+$E$2)),0)+IF($F12>0,MIN($P$3,$F12*(1+$F$2)),0)+IF($G12>0,MIN($Q$3,$G12*(1+$G$2)),0)+IF($H12>0,MIN($R$3,$H12*(1+$H$2)),0)+IF($J12>0,MIN($T$3,$J12*(1+$J$2)),0)+IF($K12>0,MIN($U$3,$K12*(1+$K$2)),0)+IF($L12>0,MIN($V$3,$L12*(1+$L$2)),0)))),MIN($S$3,$I12*(1+I$2)))) | T13: =IF($J12<=0,0,IF($Y13=8,MIN($J12*(1+J$2),MAX(0,$B13-(IF($C12>0,MIN($M$3,$C12*(1+$C$2)),0)+IF($D12>0,MIN($N$3,$D12*(1+$D$2)),0)+IF($E12>0,MIN($O$3,$E12*(1+$E$2)),0)+IF($F12>0,MIN($P$3,$F12*(1+$F$2)),0)+IF($G12>0,MIN($Q$3,$G12*(1+$G$2)),0)+IF($H12>0,MIN($R$3,$H12*(1+$H$2)),0)+IF($I12>0,MIN($S$3,$I12*(1+$I$2)),0)+IF($K12>0,MIN($U$3,$K12*(1+$K$2)),0)+IF($L12>0,MIN($V$3,$L12*(1+$L$2)),0)))),MIN($T$3,$J12*(1+J$2)))) | U13: =IF($K12<=0,0,IF($Y13=9,MIN($K12*(1+K$2),MAX(0,$B13-(IF($C12>0,MIN($M$3,$C12*(1+$C$2)),0)+IF($D12>0,MIN($N$3,$D12*(1+$D$2)),0)+IF($E12>0,MIN($O$3,$E12*(1+$E$2)),0)+IF($F12>0,MIN($P$3,$F12*(1+$F$2)),0)+IF($G12>0,MIN($Q$3,$G12*(1+$G$2)),0)+IF($H12>0,MIN($R$3,$H12*(1+$H$2)),0)+IF($I12>0,MIN($S$3,$I12*(1+$I$2)),0)+IF($J12>0,MIN($T$3,$J12*(1+$J$2)),0)+IF($L12>0,MIN($V$3,$L12*(1+$L$2)),0)))),MIN($U$3,$K12*(1+K$2)))) | V13: =IF($L12<=0,0,IF($Y13=10,MIN($L12*(1+L$2),MAX(0,$B13-(IF($C12>0,MIN($M$3,$C12*(1+$C$2)),0)+IF($D12>0,MIN($N$3,$D12*(1+$D$2)),0)+IF($E12>0,MIN($O$3,$E12*(1+$E$2)),0)+IF($F12>0,MIN($P$3,$F12*(1+$F$2)),0)+IF($G12>0,MIN($Q$3,$G12*(1+$G$2)),0)+IF($H12>0,MIN($R$3,$H12*(1+$H$2)),0)+IF($I12>0,MIN($S$3,$I12*(1+$I$2)),0)+IF($J12>0,MIN($T$3,$J12*(1+$J$2)),0)+IF($K12>0,MIN($U$3,$K12*(1+$K$2)),0)))),MIN($V$3,$L12*(1+L$2)))) | W13: =ROUND(SUMPRODUCT($C12:$L12,$C$2:$L$2),2) | X13: =SUM($C13:$L13) | Y13: =IF($X12=0,"",MIN(IF($C12>0,1,'My Debts'!$B$13+1),IF($D12>0,2,'My Debts'!$B$13+1),IF($E12>0,3,'My Debts'!$B$13+1),IF($F12>0,4,'My Debts'!$B$13+1),IF($G12>0,5,'My Debts'!$B$13+1),IF($H12>0,6,'My Debts'!$B$13+1),IF($I12>0,7,'My Debts'!$B$13+1),IF($J12>0,8,'My Debts'!$B$13+1),IF($K12>0,9,'My Debts'!$B$13+1),IF($L12>0,10,'My Debts'!$B$13+1)))
A14: 9 | B14: =IF($X13>0,'My Debts'!$B$8,0) | C14: =ROUND(MAX(0,$C13*(1+C$2)-M14),2) | D14: =ROUND(MAX(0,$D13*(1+D$2)-N14),2) | E14: =ROUND(MAX(0,$E13*(1+E$2)-O14),2) | F14: =ROUND(MAX(0,$F13*(1+F$2)-P14),2) | G14: =ROUND(MAX(0,$G13*(1+G$2)-Q14),2) | H14: =ROUND(MAX(0,$H13*(1+H$2)-R14),2) | I14: =ROUND(MAX(0,$I13*(1+I$2)-S14),2) | J14: =ROUND(MAX(0,$J13*(1+J$2)-T14),2) | K14: =ROUND(MAX(0,$K13*(1+K$2)-U14),2) | L14: =ROUND(MAX(0,$L13*(1+L$2)-V14),2) | M14: =IF($C13<=0,0,IF($Y14=1,MIN($C13*(1+C$2),MAX(0,$B14-(IF($D13>0,MIN($N$3,$D13*(1+$D$2)),0)+IF($E13>0,MIN($O$3,$E13*(1+$E$2)),0)+IF($F13>0,MIN($P$3,$F13*(1+$F$2)),0)+IF($G13>0,MIN($Q$3,$G13*(1+$G$2)),0)+IF($H13>0,MIN($R$3,$H13*(1+$H$2)),0)+IF($I13>0,MIN($S$3,$I13*(1+$I$2)),0)+IF($J13>0,MIN($T$3,$J13*(1+$J$2)),0)+IF($K13>0,MIN($U$3,$K13*(1+$K$2)),0)+IF($L13>0,MIN($V$3,$L13*(1+$L$2)),0)))),MIN($M$3,$C13*(1+C$2)))) | N14: =IF($D13<=0,0,IF($Y14=2,MIN($D13*(1+D$2),MAX(0,$B14-(IF($C13>0,MIN($M$3,$C13*(1+$C$2)),0)+IF($E13>0,MIN($O$3,$E13*(1+$E$2)),0)+IF($F13>0,MIN($P$3,$F13*(1+$F$2)),0)+IF($G13>0,MIN($Q$3,$G13*(1+$G$2)),0)+IF($H13>0,MIN($R$3,$H13*(1+$H$2)),0)+IF($I13>0,MIN($S$3,$I13*(1+$I$2)),0)+IF($J13>0,MIN($T$3,$J13*(1+$J$2)),0)+IF($K13>0,MIN($U$3,$K13*(1+$K$2)),0)+IF($L13>0,MIN($V$3,$L13*(1+$L$2)),0)))),MIN($N$3,$D13*(1+D$2)))) | O14: =IF($E13<=0,0,IF($Y14=3,MIN($E13*(1+E$2),MAX(0,$B14-(IF($C13>0,MIN($M$3,$C13*(1+$C$2)),0)+IF($D13>0,MIN($N$3,$D13*(1+$D$2)),0)+IF($F13>0,MIN($P$3,$F13*(1+$F$2)),0)+IF($G13>0,MIN($Q$3,$G13*(1+$G$2)),0)+IF($H13>0,MIN($R$3,$H13*(1+$H$2)),0)+IF($I13>0,MIN($S$3,$I13*(1+$I$2)),0)+IF($J13>0,MIN($T$3,$J13*(1+$J$2)),0)+IF($K13>0,MIN($U$3,$K13*(1+$K$2)),0)+IF($L13>0,MIN($V$3,$L13*(1+$L$2)),0)))),MIN($O$3,$E13*(1+E$2)))) | P14: =IF($F13<=0,0,IF($Y14=4,MIN($F13*(1+F$2),MAX(0,$B14-(IF($C13>0,MIN($M$3,$C13*(1+$C$2)),0)+IF($D13>0,MIN($N$3,$D13*(1+$D$2)),0)+IF($E13>0,MIN($O$3,$E13*(1+$E$2)),0)+IF($G13>0,MIN($Q$3,$G13*(1+$G$2)),0)+IF($H13>0,MIN($R$3,$H13*(1+$H$2)),0)+IF($I13>0,MIN($S$3,$I13*(1+$I$2)),0)+IF($J13>0,MIN($T$3,$J13*(1+$J$2)),0)+IF($K13>0,MIN($U$3,$K13*(1+$K$2)),0)+IF($L13>0,MIN($V$3,$L13*(1+$L$2)),0)))),MIN($P$3,$F13*(1+F$2)))) | Q14: =IF($G13<=0,0,IF($Y14=5,MIN($G13*(1+G$2),MAX(0,$B14-(IF($C13>0,MIN($M$3,$C13*(1+$C$2)),0)+IF($D13>0,MIN($N$3,$D13*(1+$D$2)),0)+IF($E13>0,MIN($O$3,$E13*(1+$E$2)),0)+IF($F13>0,MIN($P$3,$F13*(1+$F$2)),0)+IF($H13>0,MIN($R$3,$H13*(1+$H$2)),0)+IF($I13>0,MIN($S$3,$I13*(1+$I$2)),0)+IF($J13>0,MIN($T$3,$J13*(1+$J$2)),0)+IF($K13>0,MIN($U$3,$K13*(1+$K$2)),0)+IF($L13>0,MIN($V$3,$L13*(1+$L$2)),0)))),MIN($Q$3,$G13*(1+G$2)))) | R14: =IF($H13<=0,0,IF($Y14=6,MIN($H13*(1+H$2),MAX(0,$B14-(IF($C13>0,MIN($M$3,$C13*(1+$C$2)),0)+IF($D13>0,MIN($N$3,$D13*(1+$D$2)),0)+IF($E13>0,MIN($O$3,$E13*(1+$E$2)),0)+IF($F13>0,MIN($P$3,$F13*(1+$F$2)),0)+IF($G13>0,MIN($Q$3,$G13*(1+$G$2)),0)+IF($I13>0,MIN($S$3,$I13*(1+$I$2)),0)+IF($J13>0,MIN($T$3,$J13*(1+$J$2)),0)+IF($K13>0,MIN($U$3,$K13*(1+$K$2)),0)+IF($L13>0,MIN($V$3,$L13*(1+$L$2)),0)))),MIN($R$3,$H13*(1+H$2)))) | S14: =IF($I13<=0,0,IF($Y14=7,MIN($I13*(1+I$2),MAX(0,$B14-(IF($C13>0,MIN($M$3,$C13*(1+$C$2)),0)+IF($D13>0,MIN($N$3,$D13*(1+$D$2)),0)+IF($E13>0,MIN($O$3,$E13*(1+$E$2)),0)+IF($F13>0,MIN($P$3,$F13*(1+$F$2)),0)+IF($G13>0,MIN($Q$3,$G13*(1+$G$2)),0)+IF($H13>0,MIN($R$3,$H13*(1+$H$2)),0)+IF($J13>0,MIN($T$3,$J13*(1+$J$2)),0)+IF($K13>0,MIN($U$3,$K13*(1+$K$2)),0)+IF($L13>0,MIN($V$3,$L13*(1+$L$2)),0)))),MIN($S$3,$I13*(1+I$2)))) | T14: =IF($J13<=0,0,IF($Y14=8,MIN($J13*(1+J$2),MAX(0,$B14-(IF($C13>0,MIN($M$3,$C13*(1+$C$2)),0)+IF($D13>0,MIN($N$3,$D13*(1+$D$2)),0)+IF($E13>0,MIN($O$3,$E13*(1+$E$2)),0)+IF($F13>0,MIN($P$3,$F13*(1+$F$2)),0)+IF($G13>0,MIN($Q$3,$G13*(1+$G$2)),0)+IF($H13>0,MIN($R$3,$H13*(1+$H$2)),0)+IF($I13>0,MIN($S$3,$I13*(1+$I$2)),0)+IF($K13>0,MIN($U$3,$K13*(1+$K$2)),0)+IF($L13>0,MIN($V$3,$L13*(1+$L$2)),0)))),MIN($T$3,$J13*(1+J$2)))) | U14: =IF($K13<=0,0,IF($Y14=9,MIN($K13*(1+K$2),MAX(0,$B14-(IF($C13>0,MIN($M$3,$C13*(1+$C$2)),0)+IF($D13>0,MIN($N$3,$D13*(1+$D$2)),0)+IF($E13>0,MIN($O$3,$E13*(1+$E$2)),0)+IF($F13>0,MIN($P$3,$F13*(1+$F$2)),0)+IF($G13>0,MIN($Q$3,$G13*(1+$G$2)),0)+IF($H13>0,MIN($R$3,$H13*(1+$H$2)),0)+IF($I13>0,MIN($S$3,$I13*(1+$I$2)),0)+IF($J13>0,MIN($T$3,$J13*(1+$J$2)),0)+IF($L13>0,MIN($V$3,$L13*(1+$L$2)),0)))),MIN($U$3,$K13*(1+K$2)))) | V14: =IF($L13<=0,0,IF($Y14=10,MIN($L13*(1+L$2),MAX(0,$B14-(IF($C13>0,MIN($M$3,$C13*(1+$C$2)),0)+IF($D13>0,MIN($N$3,$D13*(1+$D$2)),0)+IF($E13>0,MIN($O$3,$E13*(1+$E$2)),0)+IF($F13>0,MIN($P$3,$F13*(1+$F$2)),0)+IF($G13>0,MIN($Q$3,$G13*(1+$G$2)),0)+IF($H13>0,MIN($R$3,$H13*(1+$H$2)),0)+IF($I13>0,MIN($S$3,$I13*(1+$I$2)),0)+IF($J13>0,MIN($T$3,$J13*(1+$J$2)),0)+IF($K13>0,MIN($U$3,$K13*(1+$K$2)),0)))),MIN($V$3,$L13*(1+L$2)))) | W14: =ROUND(SUMPRODUCT($C13:$L13,$C$2:$L$2),2) | X14: =SUM($C14:$L14) | Y14: =IF($X13=0,"",MIN(IF($C13>0,1,'My Debts'!$B$13+1),IF($D13>0,2,'My Debts'!$B$13+1),IF($E13>0,3,'My Debts'!$B$13+1),IF($F13>0,4,'My Debts'!$B$13+1),IF($G13>0,5,'My Debts'!$B$13+1),IF($H13>0,6,'My Debts'!$B$13+1),IF($I13>0,7,'My Debts'!$B$13+1),IF($J13>0,8,'My Debts'!$B$13+1),IF($K13>0,9,'My Debts'!$B$13+1),IF($L13>0,10,'My Debts'!$B$13+1)))
